Workbook

Sheet Sheet2 (2)
A1: s.no | B1: address | C1: bank | D1: coord_x | E1: coord_y | F1: {=TRANSPOSE(Sheet1!A2:A51)} -> PSP - 4ª Esquadra (Folgosa) | G1: PSP - 18th Police station (Campo Grande) | H1: PSP - 3rd Division of Lisbon | I1: Comando Metropolitano de Lisboa da PSP | J1: PSP - 37th Police station (Serafina) | K1: PSP - 3ª Esquadra (Bairro Alto) | L1: PSP - 14ª Esquadra (Chelas) | M1: PSP - 22ª Esquadra (Rato) | N1: PSP - Police 2nd Division - Olivais Sul | O1: National Directorate of Police | P1: PSP - 5ª Divisão Policial de Lisboa (Penha de França) | Q1: PSP - 4ª Divisão Policial / 28ª Esquadra (Calvário) / 4ª Esquadra de Investigação Criminal de Lisboa | R1: PSP - 24th Squadron (Campo de Ourique) | S1: PSP - Divisão de Investigação Criminal de Lisboa | T1: 15ª Esquadra - Caminhos de Ferro | U1: PSP - 40ª Esquadra (Parque das Nações) | V1: PSP - 41st Squadron (Lumiar) | W1: PSP - 12ª Esquadra (Olaias) | X1: PSP - 21th Squadron (Campolide) | Y1: PSP - 19th Police station (Telheiras) | Z1: PSP - Esquadra de Turismo | AA1: 1.ª e 2.ª Esquadra de Segurança a Instalações Diplomatas - Divisão de Segurança a Instalações | AB1: PSP - 2ª Esquadra (Praça do Comércio) | AC1: PSP - 71st Precinct (Odivelas) | AD1: PSP 20ª Esquadra | AE1: PSP - 26th Squadron (Belém) | AF1: PSP - Esquadra de Investigação Criminal CP/Metro | AG1: PSP - Divisão de Trânsito | AH1: 2.º Esquadra - Baixa Pombalina | AI1: PSP - 30ª Esquadra (Lapa) | AJ1: Polícia de Segurança Pública - Divisão de Segurança Aeroportuária de Lisboa | AK1: Esquadra de Segurança e Controlo | AL1: PSP - Divisão Policial / Posto Policial do Tribunal de Instrução Criminal | AM1: PSP - 36ª Esquadra (Bairro Padre Cruz) | AN1: PSP - 32ª Esquadra (Horta Nova de Telheiras) | AO1: PSP - Posto Policial do Centro Comercial Colombo | AP1: 1ª DIVISÃO POLICIAL - Gomes Freire | AQ1: SAD PSP | AR1: PSP - 4ª Esquadra de Segurança a Transportes Públicos (Gare do Oriente) | AS1: 34ª Esquadra - Olivais | AT1: Municipal Police of Lisbon | AU1: PSP - Corpo de Intervenção | AV1: 5ª Esquadra de Investigação Criminal de Lisboa | AW1: PSP - Divisão de Segurança a Transportes Públicos de Lisboa | AX1: PSP - Esquadra de Turismo | AY1: DIC Lisboa | AZ1: PSP - Lost Property Section Lisbon | BA1: 9ª Esquadra de Investigação Criminal - Trânsito | BB1: PSP - 78ª Esquadra (Camarate) | BC1: PSP - Esquadra de Turismo e Secção de Achados (Santa Apolónia)
A2: 1 | B2: Calçada Cascão 36 | C2: Caixa ATM | D2: 38.71414 | E2: -9.1252606 | F2: {=getdistance($D$2,$E$2,Sheet1!$B2,Sheet1!$C2)} -> #NAME? | G2: {=getdistance($D$2,$E$2,Sheet1!$B2,Sheet1!$C2)} -> #NAME? | H2: {=getdistance($D$2,$E$2,Sheet1!D2,Sheet1!E2)} -> #NAME? | I2: {=getdistance($D$2,$E$2,Sheet1!E2,Sheet1!F1)} -> #NAME? | J2: {=getdistance($D$2,$E$2,Sheet1!F1,Sheet1!G1)} -> #NAME? | K2: {=getdistance($D$2,$E$2,Sheet1!G1,Sheet1!H1)} -> #NAME? | L2: {=getdistance($D$2,$E$2,Sheet1!H1,Sheet1!I1)} -> #NAME? | M2: {=getdistance($D$2,$E$2,Sheet1!I1,Sheet1!J1)} -> #NAME? | N2: {=getdistance($D$2,$E$2,Sheet1!J1,Sheet1!K1)} -> #NAME? | O2: =(($D$2-Sheet1!K1)^2+ ('Sheet2 (2)'!$E$2-Sheet1!L1)^2)^0.5 -> 39.775055 | P2: =(($D$2-Sheet1!L1)^2+ ('Sheet2 (2)'!$E$2-Sheet1!M1)^2)^0.5 -> 39.775055 | Q2: =(($D$2-Sheet1!M1)^2+ ('Sheet2 (2)'!$E$2-Sheet1!N1)^2)^0.5 -> 39.775055 | R2: =(($D$2-Sheet1!N1)^2+ ('Sheet2 (2)'!$E$2-Sheet1!O1)^2)^0.5 -> 39.775055 | S2: =(($D$2-Sheet1!O1)^2+ ('Sheet2 (2)'!$E$2-Sheet1!P1)^2)^0.5 -> 39.775055 | T2: =(($D$2-Sheet1!P1)^2+ ('Sheet2 (2)'!$E$2-Sheet1!Q1)^2)^0.5 -> 39.775055 | U2: =(($D$2-Sheet1!Q1)^2+ ('Sheet2 (2)'!$E$2-Sheet1!R1)^2)^0.5 -> 39.775055 | V2: =(($D$2-Sheet1!R1)^2+ ('Sheet2 (2)'!$E$2-Sheet1!S1)^2)^0.5 -> 39.775055 | ... BJ2: =(($D$2-Sheet1!BF1)^2+ ('Sheet2 (2)'!$E$2-Sheet1!BG1)^2)^0.5 -> 39.775055
A3: 2 | B3: Av. Gomes Pereira 2A | C3: BBVA | D3: 38.750468 | E3: -9.1976682 | F3: {=getdistance($D$2,$E$2,Sheet1!B3,Sheet1!C3)} -> #NAME? | G3: =SQRT((E3-Sheet1!C3)^2+ ('Sheet2 (2)'!F3-Sheet1!D3)^2) -> #NAME? | H3: =SQRT((F3-Sheet1!D3)^2+ ('Sheet2 (2)'!G3-Sheet1!E3)^2) -> #NAME? | I3: =SQRT((G3-Sheet1!E3)^2+ ('Sheet2 (2)'!H3-Sheet1!F2)^2) -> #NAME? | J3: =SQRT((H3-Sheet1!F2)^2+ ('Sheet2 (2)'!I3-Sheet1!G2)^2) -> #NAME? | K3: =SQRT((I3-Sheet1!G2)^2+ ('Sheet2 (2)'!J3-Sheet1!H2)^2) -> #NAME? | L3: =SQRT((J3-Sheet1!H2)^2+ ('Sheet2 (2)'!K3-Sheet1!I2)^2) -> #NAME? | M3: =SQRT((K3-Sheet1!I2)^2+ ('Sheet2 (2)'!L3-Sheet1!J2)^2) -> #NAME? | N3: =SQRT((L3-Sheet1!J2)^2+ ('Sheet2 (2)'!M3-Sheet1!K2)^2) -> #NAME? | O3: =SQRT((M3-Sheet1!K2)^2+ ('Sheet2 (2)'!N3-Sheet1!L2)^2) -> #NAME? | P3: =SQRT((N3-Sheet1!L2)^2+ ('Sheet2 (2)'!O3-Sheet1!M2)^2) -> #NAME? | Q3: =SQRT((O3-Sheet1!M2)^2+ ('Sheet2 (2)'!P3-Sheet1!N2)^2) -> #NAME? | ... BJ3: =SQRT((BH3-Sheet1!BF2)^2+ ('Sheet2 (2)'!BI3-Sheet1!BG2)^2) -> #NAME?
A4: 3 | B4: floor 1 · Humberto Delgado Airport | C4: ATM | D4: 38.770401 | E4: -9.1286704 | F4: =SQRT((D4-Sheet1!B4)^2+ ('Sheet2 (2)'!E4-Sheet1!C4)^2) -> 0.074622346 | G4: =SQRT((E4-Sheet1!C4)^2+ ('Sheet2 (2)'!F4-Sheet1!D4)^2) -> 0.10262213 | H4: =SQRT((F4-Sheet1!D4)^2+ ('Sheet2 (2)'!G4-Sheet1!E4)^2) -> 0.12688498 | I4: =SQRT((G4-Sheet1!E4)^2+ ('Sheet2 (2)'!H4-Sheet1!F3)^2) -> 0.16319038 | J4: =SQRT((H4-Sheet1!F3)^2+ ('Sheet2 (2)'!I4-Sheet1!G3)^2) -> 0.20671453 | K4: =SQRT((I4-Sheet1!G3)^2+ ('Sheet2 (2)'!J4-Sheet1!H3)^2) -> 0.26336666 | L4: =SQRT((J4-Sheet1!H3)^2+ ('Sheet2 (2)'!K4-Sheet1!I3)^2) -> 0.33480277 | M4: =SQRT((K4-Sheet1!I3)^2+ ('Sheet2 (2)'!L4-Sheet1!J3)^2) -> 0.42597522 | N4: =SQRT((L4-Sheet1!J3)^2+ ('Sheet2 (2)'!M4-Sheet1!K3)^2) -> 0.5418005 | O4: =SQRT((M4-Sheet1!K3)^2+ ('Sheet2 (2)'!N4-Sheet1!L3)^2) -> 0.68920438 | P4: =SQRT((N4-Sheet1!L3)^2+ ('Sheet2 (2)'!O4-Sheet1!M3)^2) -> 0.87667009 | Q4: =SQRT((O4-Sheet1!M3)^2+ ('Sheet2 (2)'!P4-Sheet1!N3)^2) -> 1.1151471 | ... BJ4: =SQRT((BH4-Sheet1!BF3)^2+ ('Sheet2 (2)'!BI4-Sheet1!BG3)^2) -> 56176.345
A5: 4 | B5: Floor G Mercado Municipal de Benfica | C5: Multibanco | D5: 38.75095 | E5: -9.2061391 | F5: =SQRT((D5-Sheet1!B5)^2+ ('Sheet2 (2)'!E5-Sheet1!C5)^2) -> 0.10766717 | G5: =SQRT((E5-Sheet1!C5)^2+ ('Sheet2 (2)'!F5-Sheet1!D5)^2) -> 0.14931507 | H5: =SQRT((F5-Sheet1!D5)^2+ ('Sheet2 (2)'!G5-Sheet1!E5)^2) -> 0.18408479 | I5: =SQRT((G5-Sheet1!E5)^2+ ('Sheet2 (2)'!H5-Sheet1!F4)^2) -> 0.23702784 | J5: =SQRT((H5-Sheet1!F4)^2+ ('Sheet2 (2)'!I5-Sheet1!G4)^2) -> 0.30011566 | K5: =SQRT((I5-Sheet1!G4)^2+ ('Sheet2 (2)'!J5-Sheet1!H4)^2) -> 0.38242856 | L5: =SQRT((J5-Sheet1!H4)^2+ ('Sheet2 (2)'!K5-Sheet1!I4)^2) -> 0.4861286 | M5: =SQRT((K5-Sheet1!I4)^2+ ('Sheet2 (2)'!L5-Sheet1!J4)^2) -> 0.61852455 | N5: =SQRT((L5-Sheet1!J4)^2+ ('Sheet2 (2)'!M5-Sheet1!K4)^2) -> 0.78669793 | O5: =SQRT((M5-Sheet1!K4)^2+ ('Sheet2 (2)'!N5-Sheet1!L4)^2) -> 1.0007329 | P5: =SQRT((N5-Sheet1!L4)^2+ ('Sheet2 (2)'!O5-Sheet1!M4)^2) -> 1.2729336 | Q5: =SQRT((O5-Sheet1!M4)^2+ ('Sheet2 (2)'!P5-Sheet1!N4)^2) -> 1.6192054 | ... BJ5: =SQRT((BH5-Sheet1!BF4)^2+ ('Sheet2 (2)'!BI5-Sheet1!BG4)^2) -> 81568.634
A6: 5 | B6: Av. Dom João II 25 | C6: Multibanco | D6: 38.766097 | E6: -9.0983188 | F6: =SQRT((D6-Sheet1!B6)^2+ ('Sheet2 (2)'!E6-Sheet1!C6)^2) -> 0.079993913 | G6: =SQRT((E6-Sheet1!C6)^2+ ('Sheet2 (2)'!F6-Sheet1!D6)^2) -> 0.10848016 | H6: =SQRT((F6-Sheet1!D6)^2+ ('Sheet2 (2)'!G6-Sheet1!E6)^2) -> 0.1347849 | I6: =SQRT((G6-Sheet1!E6)^2+ ('Sheet2 (2)'!H6-Sheet1!F5)^2) -> 0.17301709 | J6: =SQRT((H6-Sheet1!F5)^2+ ('Sheet2 (2)'!I6-Sheet1!G5)^2) -> 0.21932142 | K6: =SQRT((I6-Sheet1!G5)^2+ ('Sheet2 (2)'!J6-Sheet1!H5)^2) -> 0.27935067 | L6: =SQRT((J6-Sheet1!H5)^2+ ('Sheet2 (2)'!K6-Sheet1!I5)^2) -> 0.35516008 | M6: =SQRT((K6-Sheet1!I5)^2+ ('Sheet2 (2)'!L6-Sheet1!J5)^2) -> 0.45185781 | N6: =SQRT((L6-Sheet1!J5)^2+ ('Sheet2 (2)'!M6-Sheet1!K5)^2) -> 0.57472964 | O6: =SQRT((M6-Sheet1!K5)^2+ ('Sheet2 (2)'!N6-Sheet1!L5)^2) -> 0.73108799 | P6: =SQRT((N6-Sheet1!L5)^2+ ('Sheet2 (2)'!O6-Sheet1!M5)^2) -> 0.92994828 | Q6: =SQRT((O6-Sheet1!M5)^2+ ('Sheet2 (2)'!P6-Sheet1!N5)^2) -> 1.1829174 | ... BJ6: =SQRT((BH6-Sheet1!BF5)^2+ ('Sheet2 (2)'!BI6-Sheet1!BG5)^2) -> 59590.333
A7: 6 | B7: R. Luís Cristino da Silva 239A | C7: Multibanco | D7: 38.758214 | E7: -9.1231879 | F7: =SQRT((D7-Sheet1!B7)^2+ ('Sheet2 (2)'!E7-Sheet1!C7)^2) -> 0.04983667 | G7: =SQRT((E7-Sheet1!C7)^2+ ('Sheet2 (2)'!F7-Sheet1!D7)^2) -> 0.054422244 | H7: =SQRT((F7-Sheet1!D7)^2+ ('Sheet2 (2)'!G7-Sheet1!E7)^2) -> 0.073793457 | I7: =SQRT((G7-Sheet1!E7)^2+ ('Sheet2 (2)'!H7-Sheet1!F6)^2) -> 0.091691084 | J7: =SQRT((H7-Sheet1!F6)^2+ ('Sheet2 (2)'!I7-Sheet1!G6)^2) -> 0.11769762 | K7: =SQRT((I7-Sheet1!G6)^2+ ('Sheet2 (2)'!J7-Sheet1!H6)^2) -> 0.1491978 | L7: =SQRT((J7-Sheet1!H6)^2+ ('Sheet2 (2)'!K7-Sheet1!I6)^2) -> 0.19003345 | M7: =SQRT((K7-Sheet1!I6)^2+ ('Sheet2 (2)'!L7-Sheet1!J6)^2) -> 0.24160442 | N7: =SQRT((L7-Sheet1!J6)^2+ ('Sheet2 (2)'!M7-Sheet1!K6)^2) -> 0.30738479 | O7: =SQRT((M7-Sheet1!K6)^2+ ('Sheet2 (2)'!N7-Sheet1!L6)^2) -> 0.39097072 | P7: =SQRT((N7-Sheet1!L6)^2+ ('Sheet2 (2)'!O7-Sheet1!M6)^2) -> 0.49733642 | Q7: =SQRT((O7-Sheet1!M6)^2+ ('Sheet2 (2)'!P7-Sheet1!N6)^2) -> 0.63261491 | ... BJ7: =SQRT((BH7-Sheet1!BF6)^2+ ('Sheet2 (2)'!BI7-Sheet1!BG6)^2) -> 31868.573
A8: 7 | B8: R. Luz Soriano 67 3º Andar - Sala 42A | C8: ATM Express | D8: 38.71239 | E8: -9.1457974 | F8: =SQRT((D8-Sheet1!B8)^2+ ('Sheet2 (2)'!E8-Sheet1!C8)^2) -> 0.051582414 | G8: =SQRT((E8-Sheet1!C8)^2+ ('Sheet2 (2)'!F8-Sheet1!D8)^2) -> 0.060439285 | H8: =SQRT((F8-Sheet1!D8)^2+ ('Sheet2 (2)'!G8-Sheet1!E8)^2) -> 0.079458496 | I8: =SQRT((G8-Sheet1!E8)^2+ ('Sheet2 (2)'!H8-Sheet1!F7)^2) -> 0.099832659 | J8: =SQRT((H8-Sheet1!F7)^2+ ('Sheet2 (2)'!I8-Sheet1!G7)^2) -> 0.12759394 | K8: =SQRT((I8-Sheet1!G7)^2+ ('Sheet2 (2)'!J8-Sheet1!H7)^2) -> 0.16200856 | L8: =SQRT((J8-Sheet1!H7)^2+ ('Sheet2 (2)'!K8-Sheet1!I7)^2) -> 0.20622072 | M8: =SQRT((K8-Sheet1!I7)^2+ ('Sheet2 (2)'!L8-Sheet1!J7)^2) -> 0.26224751 | N8: =SQRT((L8-Sheet1!J7)^2+ ('Sheet2 (2)'!M8-Sheet1!K7)^2) -> 0.33361766 | O8: =SQRT((M8-Sheet1!K7)^2+ ('Sheet2 (2)'!N8-Sheet1!L7)^2) -> 0.42435186 | P8: =SQRT((N8-Sheet1!L7)^2+ ('Sheet2 (2)'!O8-Sheet1!M7)^2) -> 0.53979185 | Q8: =SQRT((O8-Sheet1!M7)^2+ ('Sheet2 (2)'!P8-Sheet1!N7)^2) -> 0.68662198 | ... BJ8: =SQRT((BH8-Sheet1!BF7)^2+ ('Sheet2 (2)'!BI8-Sheet1!BG7)^2) -> 34589.181
A9: 8 | B9: R. Áurea 223 | C9: Multibanco | D9: 38.711761 | E9: -9.139086 | F9: =SQRT((D9-Sheet1!B9)^2+ ('Sheet2 (2)'!E9-Sheet1!C9)^2) -> 0.018865003 | G9: =SQRT((E9-Sheet1!C9)^2+ ('Sheet2 (2)'!F9-Sheet1!D9)^2) -> 0.025206543 | H9: =SQRT((F9-Sheet1!D9)^2+ ('Sheet2 (2)'!G9-Sheet1!E9)^2) -> 0.031484252 | I9: =SQRT((G9-Sheet1!E9)^2+ ('Sheet2 (2)'!H9-Sheet1!F8)^2) -> 0.040331476 | J9: =SQRT((H9-Sheet1!F8)^2+ ('Sheet2 (2)'!I9-Sheet1!G8)^2) -> 0.051165282 | K9: =SQRT((I9-Sheet1!G8)^2+ ('Sheet2 (2)'!J9-Sheet1!H8)^2) -> 0.065149935 | L9: =SQRT((J9-Sheet1!H8)^2+ ('Sheet2 (2)'!K9-Sheet1!I8)^2) -> 0.082839605 | M9: =SQRT((K9-Sheet1!I8)^2+ ('Sheet2 (2)'!L9-Sheet1!J8)^2) -> 0.10538935 | N9: =SQRT((L9-Sheet1!J8)^2+ ('Sheet2 (2)'!M9-Sheet1!K8)^2) -> 0.13404967 | O9: =SQRT((M9-Sheet1!K8)^2+ ('Sheet2 (2)'!N9-Sheet1!L8)^2) -> 0.17051753 | P9: =SQRT((N9-Sheet1!L8)^2+ ('Sheet2 (2)'!O9-Sheet1!M8)^2) -> 0.21689985 | Q9: =SQRT((O9-Sheet1!M8)^2+ ('Sheet2 (2)'!P9-Sheet1!N8)^2) -> 0.27590174 | ... BJ9: =SQRT((BH9-Sheet1!BF8)^2+ ('Sheet2 (2)'!BI9-Sheet1!BG8)^2) -> 13898.757
A10: 9 | B10: R. Cozinha Económica 101 | C10: Multibanco | D10: 38.703367 | E10: -9.1788123 | F10: =SQRT((D10-Sheet1!B10)^2+ ('Sheet2 (2)'!E10-Sheet1!C10)^2) -> 0.084406185 | G10: =SQRT((E10-Sheet1!C10)^2+ ('Sheet2 (2)'!F10-Sheet1!D10)^2) -> 0.10278659 | H10: =SQRT((F10-Sheet1!D10)^2+ ('Sheet2 (2)'!G10-Sheet1!E10)^2) -> 0.13300183 | I10: =SQRT((G10-Sheet1!E10)^2+ ('Sheet2 (2)'!H10-Sheet1!F9)^2) -> 0.16809096 | J10: =SQRT((H10-Sheet1!F9)^2+ ('Sheet2 (2)'!I10-Sheet1!G9)^2) -> 0.21434565 | K10: =SQRT((I10-Sheet1!G9)^2+ ('Sheet2 (2)'!J10-Sheet1!H9)^2) -> 0.27239425 | L10: =SQRT((J10-Sheet1!H9)^2+ ('Sheet2 (2)'!K10-Sheet1!I9)^2) -> 0.34661605 | M10: =SQRT((K10-Sheet1!I9)^2+ ('Sheet2 (2)'!L10-Sheet1!J9)^2) -> 0.44084159 | N10: =SQRT((L10-Sheet1!J9)^2+ ('Sheet2 (2)'!M10-Sheet1!K9)^2) -> 0.56078872 | O10: =SQRT((M10-Sheet1!K9)^2+ ('Sheet2 (2)'!N10-Sheet1!L9)^2) -> 0.71331992 | P10: =SQRT((N10-Sheet1!L9)^2+ ('Sheet2 (2)'!O10-Sheet1!M9)^2) -> 0.90736393 | Q10: =SQRT((O10-Sheet1!M9)^2+ ('Sheet2 (2)'!P10-Sheet1!N9)^2) -> 1.1541814 | ... BJ10: =SQRT((BH10-Sheet1!BF9)^2+ ('Sheet2 (2)'!BI10-Sheet1!BG9)^2) -> 58142.85
A11: 10 | B11: Escolas Gerais 42 | C11: Euronet Atm | D11: 38.713737 | E11: -9.1285373 | F11: =SQRT((D11-Sheet1!B11)^2+ ('Sheet2 (2)'!E11-Sheet1!C11)^2) -> 0.016408564 | G11: =SQRT((E11-Sheet1!C11)^2+ ('Sheet2 (2)'!F11-Sheet1!D11)^2) -> 0.016636323 | H11: =SQRT((F11-Sheet1!D11)^2+ ('Sheet2 (2)'!G11-Sheet1!E11)^2) -> 0.023366819 | I11: =SQRT((G11-Sheet1!E11)^2+ ('Sheet2 (2)'!H11-Sheet1!F10)^2) -> 0.028684063 | J11: =SQRT((H11-Sheet1!F10)^2+ ('Sheet2 (2)'!I11-Sheet1!G10)^2) -> 0.036997076 | K11: =SQRT((I11-Sheet1!G10)^2+ ('Sheet2 (2)'!J11-Sheet1!H10)^2) -> 0.046814091 | L11: =SQRT((J11-Sheet1!H10)^2+ ('Sheet2 (2)'!K11-Sheet1!I10)^2) -> 0.059668608 | M11: =SQRT((K11-Sheet1!I10)^2+ ('Sheet2 (2)'!L11-Sheet1!J10)^2) -> 0.075841294 | N11: =SQRT((L11-Sheet1!J10)^2+ ('Sheet2 (2)'!M11-Sheet1!K10)^2) -> 0.096499972 | O11: =SQRT((M11-Sheet1!K10)^2+ ('Sheet2 (2)'!N11-Sheet1!L10)^2) -> 0.12273608 | P11: =SQRT((N11-Sheet1!L10)^2+ ('Sheet2 (2)'!O11-Sheet1!M10)^2) -> 0.1561294 | Q11: =SQRT((O11-Sheet1!M10)^2+ ('Sheet2 (2)'!P11-Sheet1!N10)^2) -> 0.19859642 | ... BJ11: =SQRT((BH11-Sheet1!BF10)^2+ ('Sheet2 (2)'!BI11-Sheet1!BG10)^2) -> 10004.498
A12: 11 | B12: Av. de Roma 15 | C12: Terminal de auto atendimento do Banco do Brasil | D12: 38.767326 | E12: -9.1029762 | F12: =SQRT((D12-Sheet1!B12)^2+ ('Sheet2 (2)'!E12-Sheet1!C12)^2) -> 0.046492177 | G12: =SQRT((E12-Sheet1!C12)^2+ ('Sheet2 (2)'!F12-Sheet1!D12)^2) -> 0.052529278 | H12: =SQRT((F12-Sheet1!D12)^2+ ('Sheet2 (2)'!G12-Sheet1!E12)^2) -> 0.070148753 | I12: =SQRT((G12-Sheet1!E12)^2+ ('Sheet2 (2)'!H12-Sheet1!F11)^2) -> 0.087636594 | J12: =SQRT((H12-Sheet1!F11)^2+ ('Sheet2 (2)'!I12-Sheet1!G11)^2) -> 0.11225427 | K12: =SQRT((I12-Sheet1!G11)^2+ ('Sheet2 (2)'!J12-Sheet1!H11)^2) -> 0.14241205 | L12: =SQRT((J12-Sheet1!H11)^2+ ('Sheet2 (2)'!K12-Sheet1!I11)^2) -> 0.18133453 | M12: =SQRT((K12-Sheet1!I11)^2+ ('Sheet2 (2)'!L12-Sheet1!J11)^2) -> 0.23057191 | N12: =SQRT((L12-Sheet1!J11)^2+ ('Sheet2 (2)'!M12-Sheet1!K11)^2) -> 0.29333533 | O12: =SQRT((M12-Sheet1!K11)^2+ ('Sheet2 (2)'!N12-Sheet1!L11)^2) -> 0.37310726 | P12: =SQRT((N12-Sheet1!L11)^2+ ('Sheet2 (2)'!O12-Sheet1!M11)^2) -> 0.47460999 | Q12: =SQRT((O12-Sheet1!M11)^2+ ('Sheet2 (2)'!P12-Sheet1!N11)^2) -> 0.60370826 | ... BJ12: =SQRT((BH12-Sheet1!BF11)^2+ ('Sheet2 (2)'!BI12-Sheet1!BG11)^2) -> 30412.352
A13: 12 | B13: R. Tomás da Anunciação 48B | C13: Multibanco | D13: 38.716748 | E13: -9.1655396 | F13: =SQRT((D13-Sheet1!B13)^2+ ('Sheet2 (2)'!E13-Sheet1!C13)^2) -> 0.017328842 | G13: =SQRT((E13-Sheet1!C13)^2+ ('Sheet2 (2)'!F13-Sheet1!D13)^2) -> 0.021204985 | H13: =SQRT((F13-Sheet1!D13)^2+ ('Sheet2 (2)'!G13-Sheet1!E13)^2) -> 0.027385035 | I13: =SQRT((G13-Sheet1!E13)^2+ ('Sheet2 (2)'!H13-Sheet1!F12)^2) -> 0.03463512 | J13: =SQRT((H13-Sheet1!F12)^2+ ('Sheet2 (2)'!I13-Sheet1!G12)^2) -> 0.044153501 | K13: =SQRT((I13-Sheet1!G12)^2+ ('Sheet2 (2)'!J13-Sheet1!H12)^2) -> 0.056117049 | L13: =SQRT((J13-Sheet1!H12)^2+ ('Sheet2 (2)'!K13-Sheet1!I12)^2) -> 0.071404865 | M13: =SQRT((K13-Sheet1!I12)^2+ ('Sheet2 (2)'!L13-Sheet1!J12)^2) -> 0.090817278 | N13: =SQRT((L13-Sheet1!J12)^2+ ('Sheet2 (2)'!M13-Sheet1!K12)^2) -> 0.11552676 | O13: =SQRT((M13-Sheet1!K12)^2+ ('Sheet2 (2)'!N13-Sheet1!L12)^2) -> 0.14694969 | P13: =SQRT((N13-Sheet1!L12)^2+ ('Sheet2 (2)'!O13-Sheet1!M12)^2) -> 0.18692416 | Q13: =SQRT((O13-Sheet1!M12)^2+ ('Sheet2 (2)'!P13-Sheet1!N12)^2) -> 0.23777059 | ... BJ13: =SQRT((BH13-Sheet1!BF12)^2+ ('Sheet2 (2)'!BI13-Sheet1!BG12)^2) -> 11977.891
A14: 13 | B14: Alameda Santo António dos Capuchos | C14: Multibanco | D14: 38.722397 | E14: -9.1414023 | F14: =SQRT((D14-Sheet1!B14)^2+ ('Sheet2 (2)'!E14-Sheet1!C14)^2) -> 0.027443014 | G14: =SQRT((E14-Sheet1!C14)^2+ ('Sheet2 (2)'!F14-Sheet1!D14)^2) -> 0.038143951 | H14: =SQRT((F14-Sheet1!D14)^2+ ('Sheet2 (2)'!G14-Sheet1!E14)^2) -> 0.046990212 | I14: =SQRT((G14-Sheet1!E14)^2+ ('Sheet2 (2)'!H14-Sheet1!F13)^2) -> 0.060523061 | J14: =SQRT((H14-Sheet1!F13)^2+ ('Sheet2 (2)'!I14-Sheet1!G13)^2) -> 0.07662324 | K14: =SQRT((I14-Sheet1!G13)^2+ ('Sheet2 (2)'!J14-Sheet1!H13)^2) -> 0.097643033 | L14: =SQRT((J14-Sheet1!H13)^2+ ('Sheet2 (2)'!K14-Sheet1!I13)^2) -> 0.12411802 | M14: =SQRT((K14-Sheet1!I13)^2+ ('Sheet2 (2)'!L14-Sheet1!J13)^2) -> 0.15792227 | N14: =SQRT((L14-Sheet1!J13)^2+ ('Sheet2 (2)'!M14-Sheet1!K13)^2) -> 0.20085997 | O14: =SQRT((M14-Sheet1!K13)^2+ ('Sheet2 (2)'!N14-Sheet1!L13)^2) -> 0.25550768 | P14: =SQRT((N14-Sheet1!L13)^2+ ('Sheet2 (2)'!O14-Sheet1!M13)^2) -> 0.325006 | Q14: =SQRT((O14-Sheet1!M13)^2+ ('Sheet2 (2)'!P14-Sheet1!N13)^2) -> 0.41341634 | ... BJ14: =SQRT((BH14-Sheet1!BF13)^2+ ('Sheet2 (2)'!BI14-Sheet1!BG13)^2) -> 20826.144
A15: 14 | B15: R. da Voz do Operário 17 | C15: Multibanco | D15: 38.715673 | E15: -9.1291596 | F15: =SQRT((D15-Sheet1!B15)^2+ ('Sheet2 (2)'!E15-Sheet1!C15)^2) -> 0.092953093 | G15: =SQRT((E15-Sheet1!C15)^2+ ('Sheet2 (2)'!F15-Sheet1!D15)^2) -> 0.13091888 | H15: =SQRT((F15-Sheet1!D15)^2+ ('Sheet2 (2)'!G15-Sheet1!E15)^2) -> 0.16056161 | I15: =SQRT((G15-Sheet1!E15)^2+ ('Sheet2 (2)'!H15-Sheet1!F14)^2) -> 0.2071709 | J15: =SQRT((H15-Sheet1!F14)^2+ ('Sheet2 (2)'!I15-Sheet1!G14)^2) -> 0.26210649 | K15: =SQRT((I15-Sheet1!G14)^2+ ('Sheet2 (2)'!J15-Sheet1!H14)^2) -> 0.33409519 | L15: =SQRT((J15-Sheet1!H14)^2+ ('Sheet2 (2)'!K15-Sheet1!I14)^2) -> 0.42464033 | M15: =SQRT((K15-Sheet1!I14)^2+ ('Sheet2 (2)'!L15-Sheet1!J14)^2) -> 0.54031381 | N15: =SQRT((L15-Sheet1!J14)^2+ ('Sheet2 (2)'!M15-Sheet1!K14)^2) -> 0.68721061 | O15: =SQRT((M15-Sheet1!K14)^2+ ('Sheet2 (2)'!N15-Sheet1!L14)^2) -> 0.87418386 | P15: =SQRT((N15-Sheet1!L14)^2+ ('Sheet2 (2)'!O15-Sheet1!M14)^2) -> 1.1119604 | Q15: =SQRT((O15-Sheet1!M14)^2+ ('Sheet2 (2)'!P15-Sheet1!N14)^2) -> 1.4144445 | ... BJ15: =SQRT((BH15-Sheet1!BF14)^2+ ('Sheet2 (2)'!BI15-Sheet1!BG14)^2) -> 71253.639
... A124: 123 | B124: Cais do Sodré 22 | C124: Euronet ATM | D124: 38.706694 | E124: 9.1472599 | F124: =SQRT((D124-Sheet1!B124)^2+ ('Sheet2 (2)'!E124-Sheet1!C124)^2) -> 39.772862 | G124: =SQRT((E124-Sheet1!C124)^2+ ('Sheet2 (2)'!F124-Sheet1!D124)^2) -> 40.811186 | H124: =SQRT((F124-Sheet1!D124)^2+ ('Sheet2 (2)'!G124-Sheet1!E124)^2) -> 56.986257 | I124: =SQRT((G124-Sheet1!E124)^2+ ('Sheet2 (2)'!H124-Sheet1!F123)^2) -> 70.092698 | J124: =SQRT((H124-Sheet1!F123)^2+ ('Sheet2 (2)'!I124-Sheet1!G123)^2) -> 90.335042 | K124: =SQRT((I124-Sheet1!G123)^2+ ('Sheet2 (2)'!J124-Sheet1!H123)^2) -> 114.339 | L124: =SQRT((J124-Sheet1!H123)^2+ ('Sheet2 (2)'!K124-Sheet1!I123)^2) -> 145.71831 | M124: =SQRT((K124-Sheet1!I123)^2+ ('Sheet2 (2)'!L124-Sheet1!J123)^2) -> 185.22212 | N124: =SQRT((L124-Sheet1!J123)^2+ ('Sheet2 (2)'!M124-Sheet1!K123)^2) -> 235.6715 | O124: =SQRT((M124-Sheet1!K123)^2+ ('Sheet2 (2)'!N124-Sheet1!L123)^2) -> 299.74704 | P124: =SQRT((N124-Sheet1!L123)^2+ ('Sheet2 (2)'!O124-Sheet1!M123)^2) -> 381.29955 | Q124: =SQRT((O124-Sheet1!M123)^2+ ('Sheet2 (2)'!P124-Sheet1!N123)^2) -> 485.01303 | ... BJ124: =SQRT((BH124-Sheet1!BF123)^2+ ('Sheet2 (2)'!BI124-Sheet1!BG123)^2) -> 24433021

Sheet Sheet3
A1: HOW MANY TIMES A particular fregusia has been attacked (for frequency)?
A2: 1 | B2: count of the frequeny of attack of all
A3: 2 | B3: now to make data set of 2016 to 2024 we just need double need to the value of frequnecy
A4: 3 | B4: now to make data set of 2016 to 2024 we just need double need to the value of success

Sheet Original_DataSet
A2: s.no | B2: address | C2: bank | D2: atm_id | E2: coord_x | F2: coord_y | G2: freguesia | H2: parish | I2: mway_dist | J2: police_dis | K2: income | L2: density | M2: age | N2: unp_rate | O2: com_dens | P2: freq_attack | Q2: success_attack | R2: n_income | S2: n_density | T2: n_age | U2: n_unp_rate | V2: n_com_dens | W2: n_freq_attack
A3: 114 | B3: Rua Junqueira 94 Lisbon | C3: BANCO BIC PORTUGUES | D3: BP12 | E3: -9.18528 | F3: 38.69956 | G3: Alcântara | H3: 1 | I3: 1233.1995 | J3: 839.45336 | K3: 48 | L3: 0.2558 | M3: 32 | N3: 13 | O3: 9 | P3: 0 | Q3: 0 | R3: 5 | S3: 1 | T3: 2 | U3: 3 | V3: 2 | W3: 0
A4: 124 | B4: Rua Luis De Camoes 106-C Lisbon | C4: BANCO BPI S.A. | D4: BPI12 | E4: -9.18224 | F4: 38.70349 | G4: Alcântara | H4: 1 | I4: 723.0416 | J4: 407.3876 | K4: 44 | L4: 24.1571 | M4: 30 | N4: 15 | O4: 18 | P4: 0 | Q4: 0 | R4: 4 | S4: 3 | T4: 1 | U4: 4 | V4: 2 | W4: 0
A5: 186 | B5: Rua Luis De Camoes 106-C Lisbon | C5: BANCO BPI S.A. | D5: BPI82 | E5: -9.18224 | F5: 38.70349 | G5: Alcântara | H5: 1 | I5: 723.0416 | J5: 407.3876 | K5: 44 | L5: 24.1571 | M5: 30 | N5: 15 | O5: 18 | P5: 0 | Q5: 0 | R5: 4 | S5: 3 | T5: 1 | U5: 4 | V5: 2 | W5: 0
A6: 218 | B6: Rua Prior Do Crato 70 a Lisbon | C6: CAIXA GERAL DE DEPOSITOS | D6: CGD13 | E6: -9.17216 | F6: 38.70589 | G6: Alcântara | H6: 1 | I6: 599.38678 | J6: 501.75796 | K6: 30 | L6: 13.7788 | M6: 50 | N6: 17 | O6: 18 | P6: 0 | Q6: 0 | R6: 2 | S6: 2 | T6: 4 | U6: 4 | V6: 2 | W6: 0
A7: 262 | B7: Rua Da Junqueira 86 Lisbon | C7: CAIXA GERAL DE DEPOSITOS | D7: CGD61 | E7: -9.18457 | F7: 38.69984 | G7: Alcântara | H7: 1 | I7: 1174.7463 | J7: 771.67035 | K7: 44 | L7: 0.2558 | M7: 27 | N7: 13 | O7: 9 | P7: 0 | Q7: 0 | R7: 4 | S7: 1 | T7: 1 | U7: 3 | V7: 2 | W7: 0
A8: 266 | B8: Rua Leao De Oliveira S/N Lisbon | C8: CAIXA GERAL DE DEPOSITOS | D8: CGD65 | E8: -9.17875 | F8: 38.70547 | G8: Alcântara | H8: 1 | I8: 399.94386 | J8: 156.78358 | K8: 34 | L8: 20.9353 | M8: 27 | N8: 17 | O8: 18 | P8: 0 | Q8: 0 | R8: 3 | S8: 3 | T8: 1 | U8: 4 | V8: 2 | W8: 0
A9: 296 | B9: Rua Luis De Camoes 133-B Lisbon | C9: CAIXA GERAL DE DEPOSITOS | D9: CGD98 | E9: -9.18289 | F9: 38.70411 | G9: Alcântara | H9: 1 | I9: 700.21668 | J9: 456.75456 | K9: 34 | L9: 31.1863 | M9: 25 | N9: 18 | O9: 18 | P9: 0 | Q9: 0 | R9: 3 | S9: 4 | T9: 1 | U9: 4 | V9: 2 | W9: 0
A10: 362 | B10: Rua Rodrigues De Faria 103 Lisbon | C10: BANCO COMERCIAL PORTUGUES | D10: CP75 | E10: -9.17884 | F10: 38.70352 | G10: Alcântara | H10: 1 | I10: 614.48609 | J10: 127.44074 | K10: 40 | L10: 1.0554 | M10: 33 | N10: 13 | O10: 18 | P10: 0 | Q10: 0 | R10: 4 | S10: 1 | T10: 2 | U10: 3 | V10: 2 | W10: 0
A11: 381 | B11: Rua Rodrigues De Faria 103 Lisbon | C11: BANCO COMERCIAL PORTUGUES | D11: CP96 | E11: -9.17884 | F11: 38.70352 | G11: Alcântara | H11: 1 | I11: 614.48609 | J11: 127.44074 | K11: 40 | L11: 1.0554 | M11: 33 | N11: 13 | O11: 18 | P11: 0 | Q11: 0 | R11: 4 | S11: 1 | T11: 2 | U11: 3 | V11: 2 | W11: 0
A12: 430 | B12: Rua Manuel Maria Viana Lisbon | C12: MONTEPIO GERAL | D12: MG28 | E12: -9.18196 | F12: 38.69976 | G12: Alcântara | H12: 1 | I12: 1087.2719 | J12: 617.97527 | K12: 50 | L12: 2.4051 | M12: 27 | N12: 13 | O12: 9 | P12: 0 | Q12: 0 | R12: 5 | S12: 1 | T12: 1 | U12: 3 | V12: 2 | W12: 0
A13: 458 | B13: Rua Prior Crato 1 Lisbon | C13: MONTEPIO GERAL | D13: MG59 | E13: -9.17116 | F13: 38.70539 | G13: Alcântara | H13: 1 | I13: 702.49393 | J13: 571.10291 | K13: 38 | L13: 9.1194 | M13: 49 | N13: 13 | O13: 9 | P13: 0 | Q13: 0 | R13: 3 | S13: 2 | T13: 4 | U13: 3 | V13: 2 | W13: 0
A14: 460 | B14: Rua Prior Crato 1 Lisbon | C14: MONTEPIO GERAL | D14: MG62 | E14: -9.17116 | F14: 38.70539 | G14: Alcântara | H14: 1 | I14: 702.49393 | J14: 571.10291 | K14: 38 | L14: 9.1194 | M14: 49 | N14: 13 | O14: 9 | P14: 0 | Q14: 0 | R14: 3 | S14: 2 | T14: 4 | U14: 3 | V14: 2 | W14: 0
... A725: 452 | B725: Rua Vale De Santo Antonio 74 Lisbon | C725: MONTEPIO GERAL | D725: MG53 | E725: -9.12296 | F725: 38.71835 | G725: São Vicente | H725: 20 | I725: 4388.9708 | J725: 271.72197 | K725: 26 | L725: 26.5047 | M725: 59 | N725: 17 | O725: 18 | P725: 0 | Q725: 0 | R725: 2 | S725: 4 | T725: 5 | U725: 4 | V725: 2 | W725: 0

Sheet cleaned and structured data
A1: s.no | B1: address | C1: bank | D1: atm_id | E1: coord_x | F1: coord_y | G1: freguesia | H1: parish | I1: mway_dist | J1: police_dis | K1: income | L1: density | M1: age | N1: unp_rate | O1: com_dens | P1: year | Q1: freq_attack | R1: success_attack | S1: n_income | T1: n_density | U1: n_age | V1: n_unp_rate | W1: n_com_dens | X1: n_freq_attack
A2: 1 | B2: Calçada Cascão 36 | C2: Caixa ATM | E2: 38.71414 | F2: -9.1252606 | G2: Santa Maria Maior | H2: =VLOOKUP(G2,Original_DataSet!G3:H725,2,0) -> 18 | I2: 762.16278 | J2: inf
A3: 2 | B3: Av. Gomes Pereira 2A | C3: BBVA | E3: 38.750468 | F3: -9.1976682 | G3: Benfica | H3: =VLOOKUP(G3,Original_DataSet!G4:H726,2,0) -> 7 | I3: 550.33157 | J3: 650
A4: 3 | B4: floor 1 · Humberto Delgado Airport | C4: ATM | E4: 38.770401 | F4: -9.1286704 | G4: Olivais | H4: =VLOOKUP(G4,Original_DataSet!G5:H727,2,0) -> 15 | I4: 4388.9708 | J4: 950
A5: 4 | B5: Floor G Mercado Municipal de Benfica | C5: Multibanco | E5: 38.75095 | F5: -9.2061391 | G5: Benfica | H5: =VLOOKUP(G5,Original_DataSet!G6:H728,2,0) -> 7 | I5: 550.33157 | J5: 1600
A6: 5 | B6: Av. Dom João II 25 | C6: Multibanco | E6: 38.766097 | F6: -9.0983188 | G6: Parque das Nações | H6: =VLOOKUP(G6,Original_DataSet!G7:H729,2,0) -> 16 | I6: 4388.9708 | J6: 650
A7: 6 | B7: R. Luís Cristino da Silva 239A | C7: Multibanco | E7: 38.758214 | F7: -9.1231879 | G7: Areeiro | H7: =VLOOKUP(G7,Original_DataSet!G8:H730,2,0) -> 3 | I7: 372.99804 | J7: 1600
A8: 7 | B8: R. Luz Soriano 67 3º Andar - Sala 42A | C8: ATM Express | E8: 38.71239 | F8: -9.1457974 | G8: Misericórdia | H8: =VLOOKUP(G8,Original_DataSet!G9:H731,2,0) -> 14 | I8: 762.16278 | J8: 1000
A9: 8 | B9: R. Áurea 223 | C9: Multibanco | E9: 38.711761 | F9: -9.139086 | G9: Santa Maria Maior | H9: =VLOOKUP(G9,Original_DataSet!G10:H732,2,0) -> 18 | I9: 762.16278 | J9: 1800
A10: 9 | B10: R. Cozinha Económica 101 | C10: Multibanco | E10: 38.703367 | F10: -9.1788123 | G10: Estrela | H10: =VLOOKUP(G10,Original_DataSet!G11:H733,2,0) -> 11 | I10: 756.63825 | J10: 220
A11: 10 | B11: Escolas Gerais 42 | C11: Euronet Atm | E11: 38.713737 | F11: -9.1285373 | G11: Santa Maria Maior | H11: =VLOOKUP(G11,Original_DataSet!G12:H734,2,0) -> 18 | I11: 762.16278 | J11: 2800
A12: 11 | B12: Av. de Roma 15 | C12: Terminal de auto atendimento do Banco do Brasil | E12: 38.767326 | F12: -9.1029762 | G12: Alvalade | H12: =VLOOKUP(G12,Original_DataSet!G13:H735,2,0) -> 2 | I12: 4388.9708 | J12: 800
A13: 12 | B13: R. Tomás da Anunciação 48B | C13: Multibanco | E13: 38.716748 | F13: -9.1655396 | G13: Campo de Ourique | H13: =VLOOKUP(G13,Original_DataSet!G14:H736,2,0) -> 8 | I13: 762.16278 | J13: 350
A14: 13 | B14: Alameda Santo António dos Capuchos | C14: Multibanco | E14: 38.722397 | F14: -9.1414023 | G14: Arroios | H14: =VLOOKUP(G14,Original_DataSet!G15:H737,2,0) -> 4 | I14: 2939.6616 | J14: 1000
... A21: 20 | B21: Av. Infante Santo 2 | C21: Multibanco | E21: 38.703765 | F21: -9.167838 | G21: Estrela | H21: =VLOOKUP(G21,Original_DataSet!G22:H744,2,0) -> 11 | I21: 756.63825 | J21: 1700
A22: 21 | B22: Av. Brasília BP | C22: ATM do Mar | E22: 38.693816 | F22: -9.2116724 | G22: Belém | H22: =VLOOKUP(G22,Original_DataSet!G23:H745,2,0) -> 6 | I22: =#N/A -> #N/A | J22: 4700
A23: 22 | B23: Dona Estefånia | C23: ATM - Multibanco | E23: 38.727712 | F23: -9.1395096 | G23: Arroios | H23: =VLOOKUP(G23,Original_DataSet!G24:H746,2,0) -> 4 | I23: 2939.6616 | J23: 1700
A24: 23 | B24: R. Coelho da Rocha 122B | C24: Multibanco | E24: 38.71664 | F24: -9.1617492 | G24: Campo de Ourique | H24: =VLOOKUP(G24,Original_DataSet!G25:H747,2,0) -> 8 | I24: 762.16278 | J24: 650
A25: 24 | B25: Rua da Junqueira, Hospital Egas Moniz 126 | C25: Banco Montepio | ATM | E25: 38.69988 | F25: -9.187731 | G25: Alcântara | H25: 1 | I25: 1087.2719 | J25: 1400
A26: 25 | B26: Av. de Roma 39C | C26: Multibanco | E26: 38.746267 | F26: -9.1405569 | G26: Alvalade | H26: =VLOOKUP(G26,Original_DataSet!G27:H749,2,0) -> 2 | I26: 1451.2987 | J26: inf
A27: 26 | B27: Campo Pequeno 81 | C27: Multibanco | E27: 38.741297 | F27: -9.1460645 | G27: Areeiro | H27: =VLOOKUP(G27,Original_DataSet!G28:H750,2,0) -> 3 | I27: 1451.2987 | J27: 2200
A28: 27 | B28: Travessa da Água da Flor 37 | C28: ATM Express | E28: 38.713402 | F28: -9.1453113 | G28: Misericórdia | H28: =VLOOKUP(G28,Original_DataSet!G29:H751,2,0) -> 14 | I28: 762.16278 | J28: 23
A29: 28 | B29: Av. João XXI 72A | C29: Multibanco - CGD | E29: 38.74196 | F29: -9.1418409 | G29: Areeiro | H29: =VLOOKUP(G29,Original_DataSet!G30:H752,2,0) -> 3 | I29: 1451.2987 | J29: 2400
A30: 29 | B30: Restaurante Parque Verde, R. Gen. Firmino Miguel | C30: Banco Montepio | ATM | E30: 38.745954 | F30: -9.1634838 | G30: Areeiro | H30: =VLOOKUP(G30,Original_DataSet!G31:H753,2,0) -> 3 | I30: 1451.2987 | J30: 1700
A31: 30 | B31: R. Saraiva de Carvalho 386 388 | C31: ATM | E31: 38.714276 | F31: -9.1695798 | G31: Campo de Ourique | H31: =VLOOKUP(G31,Original_DataSet!G32:H754,2,0) -> 8 | I31: 762.16278 | J31: 350
A32: 31 | B32: R. Palmira 3 | C32: ATM Express | E32: 38.722656 | F32: -9.1343342 | G32: Arroios | H32: =VLOOKUP(G32,Original_DataSet!G33:H755,2,0) -> 4 | I32: 2939.6616 | J32: 850
A33: 32 | B33: R. da Palma 8 | C33: ATM Euronet | E33: 38.71679 | F33: -9.1365155 | G33: Santa Maria Maior | H33: =VLOOKUP(G33,Original_DataSet!G34:H756,2,0) -> 18 | I33: 1254.8997 | J33: 1200
A34: 33 | B34: R. da Escola Politécnica 113 | C34: Multibanco - ATM | E34: 38.717568 | F34: -9.1513077 | G34: Santo António | H34: =VLOOKUP(G34,Original_DataSet!G35:H757,2,0) -> 19 | I34: 1254.8997 | J34: 950
A35: 34 | B35: R. Tomás da Anunciação 64 B | C35: Multibanco - Caixa geral de Depósitos | E35: 38.718723 | F35: -9.1655746 | G35: Campo de Ourique | H35: =VLOOKUP(G35,Original_DataSet!G36:H758,2,0) -> 8 | I35: 1254.8997 | J35: 600
A36: 35 | B36: R. 1º de Dezembro 133 | C36: Multibanco | E36: 38.714863 | F36: -9.1406773 | G36: Santa Maria Maior | H36: =VLOOKUP(G36,Original_DataSet!G37:H759,2,0) -> 18 | I36: 762.16278 | J36: 0
A37: 36 | B37: R. do Telhal 89B | C37: ATM Express | E37: 38.72013 | F37: -9.1420885 | G37: Santo António | H37: =VLOOKUP(G37,Original_DataSet!G38:H760,2,0) -> 19 | I37: 1254.8997 | J37: 650
A38: 37 | B38: Estação comboio, Calçada da Estação | C38: Estação de comboio de Campolide | E38: 38.73222 | F38: -9.1681465 | G38: Santa Maria Maior | H38: =VLOOKUP(G38,Original_DataSet!G39:H761,2,0) -> 18 | I38: 2939.6616 | J38: 1000
A39: 38 | B39: R. Sam Levy 18 | C39: Multibanco | E39: 38.714802 | F39: -9.2144792 | G39: São Domingos de Benfica | H39: 21 | I39: 762.16278 | J39: 1500 | P39: 42851 | R39: 0
A40: 39 | B40: Calçada da Graça 16 16A | C40: ATM Express | E40: 38.715376 | F40: -9.1310965 | G40: São Vicente | H40: =VLOOKUP(G40,Original_DataSet!G41:H763,2,0) -> 20 | I40: 762.16278 | J40: 1400
A41: 40 | B41: Tv. da Boa Hora à Ajuda 17 A | C41: CGD - Multibanco | E41: 38.703522 | F41: -9.1957607 | G41: Ajuda | H41: 22 | I41: 756.63825 | J41: 650
A42: 41 | B42: Av. Combatentes da Grande Guerra 48A | C42: Multibanco - Caixa Geral de Depositos de Algés | E42: 38.700255 | F42: -9.2296346 | G42: Ajuda | H42: 22 | I42: 1087.2719 | J42: 3300
A43: 42 | B43: R. Conde Sabugosa 25, A | C43: ATM | E43: 38.746915 | F43: -9.1404133 | G43: Areeiro | H43: =VLOOKUP(G43,Original_DataSet!G44:H766,2,0) -> 3 | I43: 679.19634 | J43: 1400
A44: 43 | B44: Praça do Município 7 | C44: ATM Multibanco | E44: 38.707877 | F44: -9.1396424 | G44: Santa Maria Maior | H44: =VLOOKUP(G44,Original_DataSet!G45:H767,2,0) -> 18 | I44: 756.58391 | J44: 1000
A45: 44 | B45: Restaurante Ti Lurdes, Av. Óscar Monteiro Torres 31 B | C45: Banco Montepio | ATM | E45: 38.743196 | F45: -9.141876 | G45: Areeiro | H45: =VLOOKUP(G45,Original_DataSet!G46:H768,2,0) -> 3 | I45: 1451.2987 | J45: 1800
A46: 45 | B46: R. Manuel Bento de Sousa 130 | C46: Multibanco FCM | E46: 38.720076 | F46: -9.1398381 | G46: Belém | H46: =VLOOKUP(G46,Original_DataSet!G47:H769,2,0) -> 6 | I46: 1254.8997 | J46: 750
...

Sheet Sheet7
A2: 38.733998 | B2: -9.145642 | C2: Balcão Santander Saldanha, Lisboa | D2: Praça Duque de Saldanha 31 - B | E2: Areeiro
A3: 38.721331 | B3: -9.1487909 | C3: Citibank International Plc-branch in Portugal | D3: R. Barata Salgueiro 30 5 | E3: Santo António
A4: 38.721627 | B4: -9.1502042 | C4: Banco Best - Centro de Investimento de Lisboa | D4: R. Castilho 26 Piso 8 | E4: Santo António
A5: 38.73301 | B5: -9.1450447 | C5: ActivoBank | D5: Praça Duque de Saldanha 1 | E5: Areeiro.
A6: 38.721456 | B6: -9.1460293 | C6: ING Wholesale Banking Portugal | D6: 6th floor,, Av. da Liberdade 200 | E6: Santo António.
A7: 38.724128 | B7: -9.1497687 | C7: Banco ATLANTICO Europa | D7: Avenida da Liberdade, n.º 259 | E7: SantoAntónio.
A8: 38.726419 | B8: -9.1490766 | C8: Banco BPI | Av. Fontes Pereira de Melo | D8: Av. Fontes Pereira de Melo 4 | E8: Areeiro.
A9: 38.72315 | B9: -9.1520399 | C9: Caixa Geral de Depósitos | D9: R. Castilho 39 | E9: Santo António.
A10: 38.721183 | B10: -9.1498842 | C10: Gabinete de Estratégia e Planeamento | D10: R. Castilho 24 | E10: Santo António
A11: 38.723982 | B11: -9.1495766 | C11: Millennium bcp | D11: Av. da Liberdade 249 A | E11: Santo António
A12: 38.753765 | B12: -9.1877032 | C12: WiZink Bank, S.A.U. - Portugal | D12: Av. do Colégio Militar 37 F 6° andar | E12: Carnide
A13: 38.726797 | B13: -9.1351352 | C13: Banco de Portugal, Lisboa | D13: Av. Alm. Reis 71 | E13: Arroios
... A110: 38.766737 | B110: -9.1585174 | C110: novobanco Lumiar | D110: Av. Rainha Dona Amélia 8-C | E110: Lumiar

Sheet Sheet2
A1: s.no | B1: address | C1: bank | D1: coord_x | E1: coord_y | F1: {=TRANSPOSE(Sheet1!A2:A51)} -> PSP - 4ª Esquadra (Folgosa) | G1: PSP - 18th Police station (Campo Grande) | H1: PSP - 3rd Division of Lisbon | I1: Comando Metropolitano de Lisboa da PSP | J1: PSP - 37th Police station (Serafina) | K1: PSP - 3ª Esquadra (Bairro Alto) | L1: PSP - 14ª Esquadra (Chelas) | M1: PSP - 22ª Esquadra (Rato) | N1: PSP - Police 2nd Division - Olivais Sul | O1: National Directorate of Police | P1: PSP - 5ª Divisão Policial de Lisboa (Penha de França) | Q1: PSP - 4ª Divisão Policial / 28ª Esquadra (Calvário) / 4ª Esquadra de Investigação Criminal de Lisboa | R1: PSP - 24th Squadron (Campo de Ourique) | S1: PSP - Divisão de Investigação Criminal de Lisboa | T1: 15ª Esquadra - Caminhos de Ferro | U1: PSP - 40ª Esquadra (Parque das Nações) | V1: PSP - 41st Squadron (Lumiar) | W1: PSP - 12ª Esquadra (Olaias) | X1: PSP - 21th Squadron (Campolide) | Y1: PSP - 19th Police station (Telheiras) | Z1: PSP - Esquadra de Turismo | AA1: 1.ª e 2.ª Esquadra de Segurança a Instalações Diplomatas - Divisão de Segurança a Instalações | AB1: PSP - 2ª Esquadra (Praça do Comércio) | AC1: PSP - 71st Precinct (Odivelas) | AD1: PSP 20ª Esquadra | AE1: PSP - 26th Squadron (Belém) | AF1: PSP - Esquadra de Investigação Criminal CP/Metro | AG1: PSP - Divisão de Trânsito | AH1: 2.º Esquadra - Baixa Pombalina | AI1: PSP - 30ª Esquadra (Lapa) | AJ1: Polícia de Segurança Pública - Divisão de Segurança Aeroportuária de Lisboa | AK1: Esquadra de Segurança e Controlo | AL1: PSP - Divisão Policial / Posto Policial do Tribunal de Instrução Criminal | AM1: PSP - 36ª Esquadra (Bairro Padre Cruz) | AN1: PSP - 32ª Esquadra (Horta Nova de Telheiras) | AO1: PSP - Posto Policial do Centro Comercial Colombo | AP1: 1ª DIVISÃO POLICIAL - Gomes Freire | AQ1: SAD PSP | AR1: PSP - 4ª Esquadra de Segurança a Transportes Públicos (Gare do Oriente) | AS1: 34ª Esquadra - Olivais | AT1: Municipal Police of Lisbon | AU1: PSP - Corpo de Intervenção | AV1: 5ª Esquadra de Investigação Criminal de Lisboa | AW1: PSP - Divisão de Segurança a Transportes Públicos de Lisboa | AX1: PSP - Esquadra de Turismo | AY1: DIC Lisboa | AZ1: PSP - Lost Property Section Lisbon | BA1: 9ª Esquadra de Investigação Criminal - Trânsito | BB1: PSP - 78ª Esquadra (Camarate) | BC1: PSP - Esquadra de Turismo e Secção de Achados (Santa Apolónia)
A2: 1 | B2: Calçada Cascão 36 | C2: Caixa ATM | D2: 38.71414 | E2: -9.1252606 | F2: {=getdistance($D$2,$E$2,Sheet1!$B2,Sheet1!$C2)} -> #NAME? | G2: {=getdistance($D$2,$E$2,Sheet1!$B2,Sheet1!$C2)} -> #NAME? | H2: {=getdistance($D$2,$E$2,Sheet1!D2,Sheet1!E2)} -> #NAME? | I2: {=getdistance($D$2,$E$2,Sheet1!E2,Sheet1!F1)} -> #NAME? | J2: {=getdistance($D$2,$E$2,Sheet1!F1,Sheet1!G1)} -> #NAME? | K2: {=getdistance($D$2,$E$2,Sheet1!G1,Sheet1!H1)} -> #NAME? | L2: {=getdistance($D$2,$E$2,Sheet1!H1,Sheet1!I1)} -> #NAME? | M2: {=getdistance($D$2,$E$2,Sheet1!I1,Sheet1!J1)} -> #NAME? | N2: {=getdistance($D$2,$E$2,Sheet1!J1,Sheet1!K1)} -> #NAME? | O2: =(($D$2-Sheet1!K1)^2+ (Sheet2!$E$2-Sheet1!L1)^2)^0.5 -> 39.775055 | P2: =(($D$2-Sheet1!L1)^2+ (Sheet2!$E$2-Sheet1!M1)^2)^0.5 -> 39.775055 | Q2: =(($D$2-Sheet1!M1)^2+ (Sheet2!$E$2-Sheet1!N1)^2)^0.5 -> 39.775055 | R2: =(($D$2-Sheet1!N1)^2+ (Sheet2!$E$2-Sheet1!O1)^2)^0.5 -> 39.775055 | S2: =(($D$2-Sheet1!O1)^2+ (Sheet2!$E$2-Sheet1!P1)^2)^0.5 -> 39.775055 | T2: =(($D$2-Sheet1!P1)^2+ (Sheet2!$E$2-Sheet1!Q1)^2)^0.5 -> 39.775055 | U2: =(($D$2-Sheet1!Q1)^2+ (Sheet2!$E$2-Sheet1!R1)^2)^0.5 -> 39.775055 | V2: =(($D$2-Sheet1!R1)^2+ (Sheet2!$E$2-Sheet1!S1)^2)^0.5 -> 39.775055 | ... BJ2: =(($D$2-Sheet1!BF1)^2+ (Sheet2!$E$2-Sheet1!BG1)^2)^0.5 -> 39.775055
A3: 2 | B3: Av. Gomes Pereira 2A | C3: BBVA | D3: 38.750468 | E3: -9.1976682 | F3: {=getdistance($D$2,$E$2,Sheet1!B3,Sheet1!C3)} -> #NAME? | G3: =SQRT((E3-Sheet1!C3)^2+ (Sheet2!F3-Sheet1!D3)^2) -> #NAME? | H3: =SQRT((F3-Sheet1!D3)^2+ (Sheet2!G3-Sheet1!E3)^2) -> #NAME? | I3: =SQRT((G3-Sheet1!E3)^2+ (Sheet2!H3-Sheet1!F2)^2) -> #NAME? | J3: =SQRT((H3-Sheet1!F2)^2+ (Sheet2!I3-Sheet1!G2)^2) -> #NAME? | K3: =SQRT((I3-Sheet1!G2)^2+ (Sheet2!J3-Sheet1!H2)^2) -> #NAME? | L3: =SQRT((J3-Sheet1!H2)^2+ (Sheet2!K3-Sheet1!I2)^2) -> #NAME? | M3: =SQRT((K3-Sheet1!I2)^2+ (Sheet2!L3-Sheet1!J2)^2) -> #NAME? | N3: =SQRT((L3-Sheet1!J2)^2+ (Sheet2!M3-Sheet1!K2)^2) -> #NAME? | O3: =SQRT((M3-Sheet1!K2)^2+ (Sheet2!N3-Sheet1!L2)^2) -> #NAME? | P3: =SQRT((N3-Sheet1!L2)^2+ (Sheet2!O3-Sheet1!M2)^2) -> #NAME? | Q3: =SQRT((O3-Sheet1!M2)^2+ (Sheet2!P3-Sheet1!N2)^2) -> #NAME? | ... BJ3: =SQRT((BH3-Sheet1!BF2)^2+ (Sheet2!BI3-Sheet1!BG2)^2) -> #NAME?
A4: 3 | B4: floor 1 · Humberto Delgado Airport | C4: ATM | D4: 38.770401 | E4: -9.1286704 | F4: =SQRT((D4-Sheet1!B4)^2+ (Sheet2!E4-Sheet1!C4)^2) -> 0.074622346 | G4: =SQRT((E4-Sheet1!C4)^2+ (Sheet2!F4-Sheet1!D4)^2) -> 0.10262213 | H4: =SQRT((F4-Sheet1!D4)^2+ (Sheet2!G4-Sheet1!E4)^2) -> 0.12688498 | I4: =SQRT((G4-Sheet1!E4)^2+ (Sheet2!H4-Sheet1!F3)^2) -> 0.16319038 | J4: =SQRT((H4-Sheet1!F3)^2+ (Sheet2!I4-Sheet1!G3)^2) -> 0.20671453 | K4: =SQRT((I4-Sheet1!G3)^2+ (Sheet2!J4-Sheet1!H3)^2) -> 0.26336666 | L4: =SQRT((J4-Sheet1!H3)^2+ (Sheet2!K4-Sheet1!I3)^2) -> 0.33480277 | M4: =SQRT((K4-Sheet1!I3)^2+ (Sheet2!L4-Sheet1!J3)^2) -> 0.42597522 | N4: =SQRT((L4-Sheet1!J3)^2+ (Sheet2!M4-Sheet1!K3)^2) -> 0.5418005 | O4: =SQRT((M4-Sheet1!K3)^2+ (Sheet2!N4-Sheet1!L3)^2) -> 0.68920438 | P4: =SQRT((N4-Sheet1!L3)^2+ (Sheet2!O4-Sheet1!M3)^2) -> 0.87667009 | Q4: =SQRT((O4-Sheet1!M3)^2+ (Sheet2!P4-Sheet1!N3)^2) -> 1.1151471 | ... BJ4: =SQRT((BH4-Sheet1!BF3)^2+ (Sheet2!BI4-Sheet1!BG3)^2) -> 56176.345
A5: 4 | B5: Floor G Mercado Municipal de Benfica | C5: Multibanco | D5: 38.75095 | E5: -9.2061391 | F5: =SQRT((D5-Sheet1!B5)^2+ (Sheet2!E5-Sheet1!C5)^2) -> 0.10766717 | G5: =SQRT((E5-Sheet1!C5)^2+ (Sheet2!F5-Sheet1!D5)^2) -> 0.14931507 | H5: =SQRT((F5-Sheet1!D5)^2+ (Sheet2!G5-Sheet1!E5)^2) -> 0.18408479 | I5: =SQRT((G5-Sheet1!E5)^2+ (Sheet2!H5-Sheet1!F4)^2) -> 0.23702784 | J5: =SQRT((H5-Sheet1!F4)^2+ (Sheet2!I5-Sheet1!G4)^2) -> 0.30011566 | K5: =SQRT((I5-Sheet1!G4)^2+ (Sheet2!J5-Sheet1!H4)^2) -> 0.38242856 | L5: =SQRT((J5-Sheet1!H4)^2+ (Sheet2!K5-Sheet1!I4)^2) -> 0.4861286 | M5: =SQRT((K5-Sheet1!I4)^2+ (Sheet2!L5-Sheet1!J4)^2) -> 0.61852455 | N5: =SQRT((L5-Sheet1!J4)^2+ (Sheet2!M5-Sheet1!K4)^2) -> 0.78669793 | O5: =SQRT((M5-Sheet1!K4)^2+ (Sheet2!N5-Sheet1!L4)^2) -> 1.0007329 | P5: =SQRT((N5-Sheet1!L4)^2+ (Sheet2!O5-Sheet1!M4)^2) -> 1.2729336 | Q5: =SQRT((O5-Sheet1!M4)^2+ (Sheet2!P5-Sheet1!N4)^2) -> 1.6192054 | ... BJ5: =SQRT((BH5-Sheet1!BF4)^2+ (Sheet2!BI5-Sheet1!BG4)^2) -> 81568.634
A6: 5 | B6: Av. Dom João II 25 | C6: Multibanco | D6: 38.766097 | E6: -9.0983188 | F6: =SQRT((D6-Sheet1!B6)^2+ (Sheet2!E6-Sheet1!C6)^2) -> 0.079993913 | G6: =SQRT((E6-Sheet1!C6)^2+ (Sheet2!F6-Sheet1!D6)^2) -> 0.10848016 | H6: =SQRT((F6-Sheet1!D6)^2+ (Sheet2!G6-Sheet1!E6)^2) -> 0.1347849 | I6: =SQRT((G6-Sheet1!E6)^2+ (Sheet2!H6-Sheet1!F5)^2) -> 0.17301709 | J6: =SQRT((H6-Sheet1!F5)^2+ (Sheet2!I6-Sheet1!G5)^2) -> 0.21932142 | K6: =SQRT((I6-Sheet1!G5)^2+ (Sheet2!J6-Sheet1!H5)^2) -> 0.27935067 | L6: =SQRT((J6-Sheet1!H5)^2+ (Sheet2!K6-Sheet1!I5)^2) -> 0.35516008 | M6: =SQRT((K6-Sheet1!I5)^2+ (Sheet2!L6-Sheet1!J5)^2) -> 0.45185781 | N6: =SQRT((L6-Sheet1!J5)^2+ (Sheet2!M6-Sheet1!K5)^2) -> 0.57472964 | O6: =SQRT((M6-Sheet1!K5)^2+ (Sheet2!N6-Sheet1!L5)^2) -> 0.73108799 | P6: =SQRT((N6-Sheet1!L5)^2+ (Sheet2!O6-Sheet1!M5)^2) -> 0.92994828 | Q6: =SQRT((O6-Sheet1!M5)^2+ (Sheet2!P6-Sheet1!N5)^2) -> 1.1829174 | ... BJ6: =SQRT((BH6-Sheet1!BF5)^2+ (Sheet2!BI6-Sheet1!BG5)^2) -> 59590.333
A7: 6 | B7: R. Luís Cristino da Silva 239A | C7: Multibanco | D7: 38.758214 | E7: -9.1231879 | F7: =SQRT((D7-Sheet1!B7)^2+ (Sheet2!E7-Sheet1!C7)^2) -> 0.04983667 | G7: =SQRT((E7-Sheet1!C7)^2+ (Sheet2!F7-Sheet1!D7)^2) -> 0.054422244 | H7: =SQRT((F7-Sheet1!D7)^2+ (Sheet2!G7-Sheet1!E7)^2) -> 0.073793457 | I7: =SQRT((G7-Sheet1!E7)^2+ (Sheet2!H7-Sheet1!F6)^2) -> 0.091691084 | J7: =SQRT((H7-Sheet1!F6)^2+ (Sheet2!I7-Sheet1!G6)^2) -> 0.11769762 | K7: =SQRT((I7-Sheet1!G6)^2+ (Sheet2!J7-Sheet1!H6)^2) -> 0.1491978 | L7: =SQRT((J7-Sheet1!H6)^2+ (Sheet2!K7-Sheet1!I6)^2) -> 0.19003345 | M7: =SQRT((K7-Sheet1!I6)^2+ (Sheet2!L7-Sheet1!J6)^2) -> 0.24160442 | N7: =SQRT((L7-Sheet1!J6)^2+ (Sheet2!M7-Sheet1!K6)^2) -> 0.30738479 | O7: =SQRT((M7-Sheet1!K6)^2+ (Sheet2!N7-Sheet1!L6)^2) -> 0.39097072 | P7: =SQRT((N7-Sheet1!L6)^2+ (Sheet2!O7-Sheet1!M6)^2) -> 0.49733642 | Q7: =SQRT((O7-Sheet1!M6)^2+ (Sheet2!P7-Sheet1!N6)^2) -> 0.63261491 | ... BJ7: =SQRT((BH7-Sheet1!BF6)^2+ (Sheet2!BI7-Sheet1!BG6)^2) -> 31868.573
A8: 7 | B8: R. Luz Soriano 67 3º Andar - Sala 42A | C8: ATM Express | D8: 38.71239 | E8: -9.1457974 | F8: =SQRT((D8-Sheet1!B8)^2+ (Sheet2!E8-Sheet1!C8)^2) -> 0.051582414 | G8: =SQRT((E8-Sheet1!C8)^2+ (Sheet2!F8-Sheet1!D8)^2) -> 0.060439285 | H8: =SQRT((F8-Sheet1!D8)^2+ (Sheet2!G8-Sheet1!E8)^2) -> 0.079458496 | I8: =SQRT((G8-Sheet1!E8)^2+ (Sheet2!H8-Sheet1!F7)^2) -> 0.099832659 | J8: =SQRT((H8-Sheet1!F7)^2+ (Sheet2!I8-Sheet1!G7)^2) -> 0.12759394 | K8: =SQRT((I8-Sheet1!G7)^2+ (Sheet2!J8-Sheet1!H7)^2) -> 0.16200856 | L8: =SQRT((J8-Sheet1!H7)^2+ (Sheet2!K8-Sheet1!I7)^2) -> 0.20622072 | M8: =SQRT((K8-Sheet1!I7)^2+ (Sheet2!L8-Sheet1!J7)^2) -> 0.26224751 | N8: =SQRT((L8-Sheet1!J7)^2+ (Sheet2!M8-Sheet1!K7)^2) -> 0.33361766 | O8: =SQRT((M8-Sheet1!K7)^2+ (Sheet2!N8-Sheet1!L7)^2) -> 0.42435186 | P8: =SQRT((N8-Sheet1!L7)^2+ (Sheet2!O8-Sheet1!M7)^2) -> 0.53979185 | Q8: =SQRT((O8-Sheet1!M7)^2+ (Sheet2!P8-Sheet1!N7)^2) -> 0.68662198 | ... BJ8: =SQRT((BH8-Sheet1!BF7)^2+ (Sheet2!BI8-Sheet1!BG7)^2) -> 34589.181
A9: 8 | B9: R. Áurea 223 | C9: Multibanco | D9: 38.711761 | E9: -9.139086 | F9: =SQRT((D9-Sheet1!B9)^2+ (Sheet2!E9-Sheet1!C9)^2) -> 0.018865003 | G9: =SQRT((E9-Sheet1!C9)^2+ (Sheet2!F9-Sheet1!D9)^2) -> 0.025206543 | H9: =SQRT((F9-Sheet1!D9)^2+ (Sheet2!G9-Sheet1!E9)^2) -> 0.031484252 | I9: =SQRT((G9-Sheet1!E9)^2+ (Sheet2!H9-Sheet1!F8)^2) -> 0.040331476 | J9: =SQRT((H9-Sheet1!F8)^2+ (Sheet2!I9-Sheet1!G8)^2) -> 0.051165282 | K9: =SQRT((I9-Sheet1!G8)^2+ (Sheet2!J9-Sheet1!H8)^2) -> 0.065149935 | L9: =SQRT((J9-Sheet1!H8)^2+ (Sheet2!K9-Sheet1!I8)^2) -> 0.082839605 | M9: =SQRT((K9-Sheet1!I8)^2+ (Sheet2!L9-Sheet1!J8)^2) -> 0.10538935 | N9: =SQRT((L9-Sheet1!J8)^2+ (Sheet2!M9-Sheet1!K8)^2) -> 0.13404967 | O9: =SQRT((M9-Sheet1!K8)^2+ (Sheet2!N9-Sheet1!L8)^2) -> 0.17051753 | P9: =SQRT((N9-Sheet1!L8)^2+ (Sheet2!O9-Sheet1!M8)^2) -> 0.21689985 | Q9: =SQRT((O9-Sheet1!M8)^2+ (Sheet2!P9-Sheet1!N8)^2) -> 0.27590174 | ... BJ9: =SQRT((BH9-Sheet1!BF8)^2+ (Sheet2!BI9-Sheet1!BG8)^2) -> 13898.757
A10: 9 | B10: R. Cozinha Económica 101 | C10: Multibanco | D10: 38.703367 | E10: -9.1788123 | F10: =SQRT((D10-Sheet1!B10)^2+ (Sheet2!E10-Sheet1!C10)^2) -> 0.084406185 | G10: =SQRT((E10-Sheet1!C10)^2+ (Sheet2!F10-Sheet1!D10)^2) -> 0.10278659 | H10: =SQRT((F10-Sheet1!D10)^2+ (Sheet2!G10-Sheet1!E10)^2) -> 0.13300183 | I10: =SQRT((G10-Sheet1!E10)^2+ (Sheet2!H10-Sheet1!F9)^2) -> 0.16809096 | J10: =SQRT((H10-Sheet1!F9)^2+ (Sheet2!I10-Sheet1!G9)^2) -> 0.21434565 | K10: =SQRT((I10-Sheet1!G9)^2+ (Sheet2!J10-Sheet1!H9)^2) -> 0.27239425 | L10: =SQRT((J10-Sheet1!H9)^2+ (Sheet2!K10-Sheet1!I9)^2) -> 0.34661605 | M10: =SQRT((K10-Sheet1!I9)^2+ (Sheet2!L10-Sheet1!J9)^2) -> 0.44084159 | N10: =SQRT((L10-Sheet1!J9)^2+ (Sheet2!M10-Sheet1!K9)^2) -> 0.56078872 | O10: =SQRT((M10-Sheet1!K9)^2+ (Sheet2!N10-Sheet1!L9)^2) -> 0.71331992 | P10: =SQRT((N10-Sheet1!L9)^2+ (Sheet2!O10-Sheet1!M9)^2) -> 0.90736393 | Q10: =SQRT((O10-Sheet1!M9)^2+ (Sheet2!P10-Sheet1!N9)^2) -> 1.1541814 | ... BJ10: =SQRT((BH10-Sheet1!BF9)^2+ (Sheet2!BI10-Sheet1!BG9)^2) -> 58142.85
A11: 10 | B11: Escolas Gerais 42 | C11: Euronet Atm | D11: 38.713737 | E11: -9.1285373 | F11: =SQRT((D11-Sheet1!B11)^2+ (Sheet2!E11-Sheet1!C11)^2) -> 0.016408564 | G11: =SQRT((E11-Sheet1!C11)^2+ (Sheet2!F11-Sheet1!D11)^2) -> 0.016636323 | H11: =SQRT((F11-Sheet1!D11)^2+ (Sheet2!G11-Sheet1!E11)^2) -> 0.023366819 | I11: =SQRT((G11-Sheet1!E11)^2+ (Sheet2!H11-Sheet1!F10)^2) -> 0.028684063 | J11: =SQRT((H11-Sheet1!F10)^2+ (Sheet2!I11-Sheet1!G10)^2) -> 0.036997076 | K11: =SQRT((I11-Sheet1!G10)^2+ (Sheet2!J11-Sheet1!H10)^2) -> 0.046814091 | L11: =SQRT((J11-Sheet1!H10)^2+ (Sheet2!K11-Sheet1!I10)^2) -> 0.059668608 | M11: =SQRT((K11-Sheet1!I10)^2+ (Sheet2!L11-Sheet1!J10)^2) -> 0.075841294 | N11: =SQRT((L11-Sheet1!J10)^2+ (Sheet2!M11-Sheet1!K10)^2) -> 0.096499972 | O11: =SQRT((M11-Sheet1!K10)^2+ (Sheet2!N11-Sheet1!L10)^2) -> 0.12273608 | P11: =SQRT((N11-Sheet1!L10)^2+ (Sheet2!O11-Sheet1!M10)^2) -> 0.1561294 | Q11: =SQRT((O11-Sheet1!M10)^2+ (Sheet2!P11-Sheet1!N10)^2) -> 0.19859642 | ... BJ11: =SQRT((BH11-Sheet1!BF10)^2+ (Sheet2!BI11-Sheet1!BG10)^2) -> 10004.498
A12: 11 | B12: Av. de Roma 15 | C12: Terminal de auto atendimento do Banco do Brasil | D12: 38.767326 | E12: -9.1029762 | F12: =SQRT((D12-Sheet1!B12)^2+ (Sheet2!E12-Sheet1!C12)^2) -> 0.046492177 | G12: =SQRT((E12-Sheet1!C12)^2+ (Sheet2!F12-Sheet1!D12)^2) -> 0.052529278 | H12: =SQRT((F12-Sheet1!D12)^2+ (Sheet2!G12-Sheet1!E12)^2) -> 0.070148753 | I12: =SQRT((G12-Sheet1!E12)^2+ (Sheet2!H12-Sheet1!F11)^2) -> 0.087636594 | J12: =SQRT((H12-Sheet1!F11)^2+ (Sheet2!I12-Sheet1!G11)^2) -> 0.11225427 | K12: =SQRT((I12-Sheet1!G11)^2+ (Sheet2!J12-Sheet1!H11)^2) -> 0.14241205 | L12: =SQRT((J12-Sheet1!H11)^2+ (Sheet2!K12-Sheet1!I11)^2) -> 0.18133453 | M12: =SQRT((K12-Sheet1!I11)^2+ (Sheet2!L12-Sheet1!J11)^2) -> 0.23057191 | N12: =SQRT((L12-Sheet1!J11)^2+ (Sheet2!M12-Sheet1!K11)^2) -> 0.29333533 | O12: =SQRT((M12-Sheet1!K11)^2+ (Sheet2!N12-Sheet1!L11)^2) -> 0.37310726 | P12: =SQRT((N12-Sheet1!L11)^2+ (Sheet2!O12-Sheet1!M11)^2) -> 0.47460999 | Q12: =SQRT((O12-Sheet1!M11)^2+ (Sheet2!P12-Sheet1!N11)^2) -> 0.60370826 | ... BJ12: =SQRT((BH12-Sheet1!BF11)^2+ (Sheet2!BI12-Sheet1!BG11)^2) -> 30412.352
A13: 12 | B13: R. Tomás da Anunciação 48B | C13: Multibanco | D13: 38.716748 | E13: -9.1655396 | F13: =SQRT((D13-Sheet1!B13)^2+ (Sheet2!E13-Sheet1!C13)^2) -> 0.017328842 | G13: =SQRT((E13-Sheet1!C13)^2+ (Sheet2!F13-Sheet1!D13)^2) -> 0.021204985 | H13: =SQRT((F13-Sheet1!D13)^2+ (Sheet2!G13-Sheet1!E13)^2) -> 0.027385035 | I13: =SQRT((G13-Sheet1!E13)^2+ (Sheet2!H13-Sheet1!F12)^2) -> 0.03463512 | J13: =SQRT((H13-Sheet1!F12)^2+ (Sheet2!I13-Sheet1!G12)^2) -> 0.044153501 | K13: =SQRT((I13-Sheet1!G12)^2+ (Sheet2!J13-Sheet1!H12)^2) -> 0.056117049 | L13: =SQRT((J13-Sheet1!H12)^2+ (Sheet2!K13-Sheet1!I12)^2) -> 0.071404865 | M13: =SQRT((K13-Sheet1!I12)^2+ (Sheet2!L13-Sheet1!J12)^2) -> 0.090817278 | N13: =SQRT((L13-Sheet1!J12)^2+ (Sheet2!M13-Sheet1!K12)^2) -> 0.11552676 | O13: =SQRT((M13-Sheet1!K12)^2+ (Sheet2!N13-Sheet1!L12)^2) -> 0.14694969 | P13: =SQRT((N13-Sheet1!L12)^2+ (Sheet2!O13-Sheet1!M12)^2) -> 0.18692416 | Q13: =SQRT((O13-Sheet1!M12)^2+ (Sheet2!P13-Sheet1!N12)^2) -> 0.23777059 | ... BJ13: =SQRT((BH13-Sheet1!BF12)^2+ (Sheet2!BI13-Sheet1!BG12)^2) -> 11977.891
A14: 13 | B14: Alameda Santo António dos Capuchos | C14: Multibanco | D14: 38.722397 | E14: -9.1414023 | F14: =SQRT((D14-Sheet1!B14)^2+ (Sheet2!E14-Sheet1!C14)^2) -> 0.027443014 | G14: =SQRT((E14-Sheet1!C14)^2+ (Sheet2!F14-Sheet1!D14)^2) -> 0.038143951 | H14: =SQRT((F14-Sheet1!D14)^2+ (Sheet2!G14-Sheet1!E14)^2) -> 0.046990212 | I14: =SQRT((G14-Sheet1!E14)^2+ (Sheet2!H14-Sheet1!F13)^2) -> 0.060523061 | J14: =SQRT((H14-Sheet1!F13)^2+ (Sheet2!I14-Sheet1!G13)^2) -> 0.07662324 | K14: =SQRT((I14-Sheet1!G13)^2+ (Sheet2!J14-Sheet1!H13)^2) -> 0.097643033 | L14: =SQRT((J14-Sheet1!H13)^2+ (Sheet2!K14-Sheet1!I13)^2) -> 0.12411802 | M14: =SQRT((K14-Sheet1!I13)^2+ (Sheet2!L14-Sheet1!J13)^2) -> 0.15792227 | N14: =SQRT((L14-Sheet1!J13)^2+ (Sheet2!M14-Sheet1!K13)^2) -> 0.20085997 | O14: =SQRT((M14-Sheet1!K13)^2+ (Sheet2!N14-Sheet1!L13)^2) -> 0.25550768 | P14: =SQRT((N14-Sheet1!L13)^2+ (Sheet2!O14-Sheet1!M13)^2) -> 0.325006 | Q14: =SQRT((O14-Sheet1!M13)^2+ (Sheet2!P14-Sheet1!N13)^2) -> 0.41341634 | ... BJ14: =SQRT((BH14-Sheet1!BF13)^2+ (Sheet2!BI14-Sheet1!BG13)^2) -> 20826.144
A15: 14 | B15: R. da Voz do Operário 17 | C15: Multibanco | D15: 38.715673 | E15: -9.1291596 | F15: =SQRT((D15-Sheet1!B15)^2+ (Sheet2!E15-Sheet1!C15)^2) -> 0.092953093 | G15: =SQRT((E15-Sheet1!C15)^2+ (Sheet2!F15-Sheet1!D15)^2) -> 0.13091888 | H15: =SQRT((F15-Sheet1!D15)^2+ (Sheet2!G15-Sheet1!E15)^2) -> 0.16056161 | I15: =SQRT((G15-Sheet1!E15)^2+ (Sheet2!H15-Sheet1!F14)^2) -> 0.2071709 | J15: =SQRT((H15-Sheet1!F14)^2+ (Sheet2!I15-Sheet1!G14)^2) -> 0.26210649 | K15: =SQRT((I15-Sheet1!G14)^2+ (Sheet2!J15-Sheet1!H14)^2) -> 0.33409519 | L15: =SQRT((J15-Sheet1!H14)^2+ (Sheet2!K15-Sheet1!I14)^2) -> 0.42464033 | M15: =SQRT((K15-Sheet1!I14)^2+ (Sheet2!L15-Sheet1!J14)^2) -> 0.54031381 | N15: =SQRT((L15-Sheet1!J14)^2+ (Sheet2!M15-Sheet1!K14)^2) -> 0.68721061 | O15: =SQRT((M15-Sheet1!K14)^2+ (Sheet2!N15-Sheet1!L14)^2) -> 0.87418386 | P15: =SQRT((N15-Sheet1!L14)^2+ (Sheet2!O15-Sheet1!M14)^2) -> 1.1119604 | Q15: =SQRT((O15-Sheet1!M14)^2+ (Sheet2!P15-Sheet1!N14)^2) -> 1.4144445 | ... BJ15: =SQRT((BH15-Sheet1!BF14)^2+ (Sheet2!BI15-Sheet1!BG14)^2) -> 71253.639
... A124: 123 | B124: Cais do Sodré 22 | C124: Euronet ATM | D124: 38.706694 | E124: 9.1472599 | F124: =SQRT((D124-Sheet1!B124)^2+ (Sheet2!E124-Sheet1!C124)^2) -> 39.772862 | G124: =SQRT((E124-Sheet1!C124)^2+ (Sheet2!F124-Sheet1!D124)^2) -> 40.811186 | H124: =SQRT((F124-Sheet1!D124)^2+ (Sheet2!G124-Sheet1!E124)^2) -> 56.986257 | I124: =SQRT((G124-Sheet1!E124)^2+ (Sheet2!H124-Sheet1!F123)^2) -> 70.092698 | J124: =SQRT((H124-Sheet1!F123)^2+ (Sheet2!I124-Sheet1!G123)^2) -> 90.335042 | K124: =SQRT((I124-Sheet1!G123)^2+ (Sheet2!J124-Sheet1!H123)^2) -> 114.339 | L124: =SQRT((J124-Sheet1!H123)^2+ (Sheet2!K124-Sheet1!I123)^2) -> 145.71831 | M124: =SQRT((K124-Sheet1!I123)^2+ (Sheet2!L124-Sheet1!J123)^2) -> 185.22212 | N124: =SQRT((L124-Sheet1!J123)^2+ (Sheet2!M124-Sheet1!K123)^2) -> 235.6715 | O124: =SQRT((M124-Sheet1!K123)^2+ (Sheet2!N124-Sheet1!L123)^2) -> 299.74704 | P124: =SQRT((N124-Sheet1!L123)^2+ (Sheet2!O124-Sheet1!M123)^2) -> 381.29955 | Q124: =SQRT((O124-Sheet1!M123)^2+ (Sheet2!P124-Sheet1!N123)^2) -> 485.01303 | ... BJ124: =SQRT((BH124-Sheet1!BF123)^2+ (Sheet2!BI124-Sheet1!BG123)^2) -> 24433021

Sheet Sheet5
A1: s.no | B1: address | C1: coord_x | D1: coord_y | E1: police station name | F1: x | G1: y | H1: {=TRANSPOSE(B2:B124)} -> Calçada Cascão 36 | I1: Av. Gomes Pereira 2A | J1: floor 1 · Humberto Delgado Airport | K1: Floor G Mercado Municipal de Benfica | L1: Av. Dom João II 25 | M1: R. Luís Cristino da Silva 239A | N1: R. Luz Soriano 67 3º Andar - Sala 42A | O1: R. Áurea 223 | P1: R. Cozinha Económica 101 | Q1: Escolas Gerais 42 | R1: Av. de Roma 15 | S1: R. Tomás da Anunciação 48B | T1: Alameda Santo António dos Capuchos | U1: R. da Voz do Operário 17 | V1: Av. Gen. Roçadas 48 | W1: Av. Dom João II 24 | X1: R. Dom Pedro V 108 A | Y1: Lisboa - Cidade 47 | Z1: benfica metro station | AA1: Av. Infante Santo 2 | AB1: Av. Brasília BP | AC1: Dona Estefånia | AD1: R. Coelho da Rocha 122B | AE1: Rua da Junqueira, Hospital Egas Moniz 126 | AF1: Av. de Roma 39C | AG1: Campo Pequeno 81 | AH1: Travessa da Água da Flor 37 | AI1: Av. João XXI 72A | AJ1: Restaurante Parque Verde, R. Gen. Firmino Miguel | AK1: R. Saraiva de Carvalho 386 388 | AL1: R. Palmira 3 | AM1: R. da Palma 8 | AN1: R. da Escola Politécnica 113 | AO1: R. Tomás da Anunciação 64 B | AP1: R. 1º de Dezembro 133 | AQ1: R. do Telhal 89B | AR1: Estação comboio, Calçada da Estação | AS1: R. Sam Levy 18 | AT1: Calçada da Graça 16 16A | AU1: Tv. da Boa Hora à Ajuda 17 A | AV1: Av. Combatentes da Grande Guerra 48A | AW1: R. Conde Sabugosa 25, A | AX1: Praça do Município 7 | AY1: Restaurante Ti Lurdes, Av. Óscar Monteiro Torres 31 B | AZ1: R. Manuel Bento de Sousa 130 | BA1: Av. da Liberdade 245B | BB1: R. Dr. Eduardo Neves 9 A | BC1: R. Tomás Ribeiro 61-47 | BD1: R. de São Julião 38 | BE1: R. de Buenos Aires 12B | BF1: Av. Visc. de Valmor 68 | BG1: Av. João XXI 70C | BH1: CC de Sant'Ana 180 | BI1: Estacionamento do Mercado do Chão do Loureiro, Largo Chão do Loureiro | BJ1: Av. Fontes Pereira de Melo 42E | BK1: R. da Atalaia 204 | BL1: R. Barata Salgueiro 6A | BM1: Praça Duque da Terceira CP | BN1: R. António Pereira Carrilho | BO1: R. do Poço dos Negros 94 | BP1: Av. Brasília 7 | BQ1: R. Áurea 75 | BR1: Campo de Santa Clara | BS1: R. de São Vicente 17 | BT1: CCP - Casa Credito Popular, R. do Arco do Marquês de Alegrete | BU1: Avenida 5 de Outubro 295, D | BV1: Calçada de Santo André 10 | BW1: Alameda António Sérgio 12 D | BX1: R. Angelina Vidal 33 | BY1: Av. Alm. Reis 108 114 | BZ1: Av. da Liberdade 222 | CA1: R. dos Remédios 55 | CB1: Av. da Liberdade 131 | CC1: Lgo do Rato 7 B | CD1: R. Damasceno Monteiro 74B | CE1: R. dos Cavaleiros 68 | CF1: Av. Alm. Reis 71 | CG1: Av. Helen Keller 10 | CH1: R. do Comércio 283 | CI1: R. Alexandre Herculano 86 | CJ1: R. da Atalaia 25 | CK1: Papelaria Loja do Rato, Av. Cel. Eduardo Galhardo 3G | CL1: R. Horta Seca 11 1 | CM1: Av. Casal Ribeiro 46C | CN1: R. Morais Soares 45a | CO1: R. dos Fanqueiros 170 | CP1: CC do Marquês de Abrantes 26 | CQ1: Praça Luís de Camões 22 4º andar | CR1: R. Luís Pinto Moitinho 5B | CS1: R. de Santiago 4 | CT1: Calçada Garcia 10 | CU1: R. do Poço dos Negros 48 | CV1: R. da Escola Politécnica 73 | CW1: R. Pascoal de Melo 138A | CX1: Pç. General Domingos de Oliveira | CY1: R. Ferreira Borges 6266 | CZ1: Tribunal do Comércio de Lisboa, R. Nova do Almada 4 | DA1: Av. Alm. Reis 12 | DB1: Atrium Saldanha, Praça Duque de Saldanha 1 | DC1: Av. Álvares Cabral 49, A | DD1: Rua de S. Paulo 12A | DE1: Associação Socorros Mútuos, Largo São Cristóvão 1 | DF1: R. Palmira 66 | DG1: R. Teófilo Braga 6 | DH1: Av. das Forças Armadas 125 | DI1: R. Tomás da Anunciação 64 B | DJ1: Campo das Cebolas 26 | DK1: Cais do sodré Estação, do | DL1: Loural Ilha De Santa Maria | DM1: R. Áurea 146 | DN1: Praça Martim Moniz 564 | DO1: Av. das Descobertas | DP1: Praça da Figueira 4 | DQ1: Av. Alm. Reis 247 B C | DR1: Avenida da República, Campo Pequeno C.C | DS1: Av. da Torre de Belém 8 | DT1: Av. Fontes Pereira de Melo 35 frente | DU1: R. Infantaria 16 60 | DV1: Rua Do Laracha, 10, Escaravilheira, Escravilheira, Lisboa | DW1: Av. Alm. Reis 15 B | DX1: Praça Duque de Saldanha 21 C | DY1: Rua da Graça 104 | DZ1: Cais do Sodré 22
A2: 1 | B2: Calçada Cascão 36 | C2: 38.71414 | D2: -9.1252606 | E2: PSP - 4ª Esquadra (Folgosa) | F2: 38.717846 | G2: -9.1359409 | H2: {=getdistance($C$2,$D$2,F2,G2)} -> #NAME? | I2: {=getdistance($C$3,$D$3,F2,G2)} -> #NAME?
A3: 2 | B3: Av. Gomes Pereira 2A | C3: 38.750468 | D3: -9.1976682 | E3: PSP - 18th Police station (Campo Grande) | F3: 38.749628 | G3: -9.1468555 | H3: {=getdistance($C$2,$D$2,F3,G3)} -> #NAME? | I3: {=getdistance($C$3,$D$3,F3,G3)} -> #NAME?
A4: 3 | B4: floor 1 · Humberto Delgado Airport | C4: 38.770401 | D4: -9.1286704 | E4: PSP - 3rd Division of Lisbon | F4: 38.74579 | G4: -9.1991176 | H4: {=getdistance($C$2,$D$2,F4,G4)} -> #NAME? | I4: {=getdistance($C$3,$D$3,F4,G4)} -> #NAME?
A5: 4 | B5: Floor G Mercado Municipal de Benfica | C5: 38.75095 | D5: -9.2061391 | E5: Comando Metropolitano de Lisboa da PSP | F5: 38.780774 | G5: -9.1026849 | H5: {=getdistance($C$2,$D$2,F5,G5)} -> #NAME? | I5: {=getdistance($C$3,$D$3,F5,G5)} -> #NAME?
A6: 5 | B6: Av. Dom João II 25 | C6: 38.766097 | D6: -9.0983188 | E6: PSP - 37th Police station (Serafina) | F6: 38.734001 | G6: -9.1715917 | H6: {=getdistance($C$2,$D$2,F6,G6)} -> #NAME? | I6: {=getdistance($C$3,$D$3,F6,G6)} -> #NAME?
A7: 6 | B7: R. Luís Cristino da Silva 239A | C7: 38.758214 | D7: -9.1231879 | E7: PSP - 3ª Esquadra (Bairro Alto) | F7: 38.71343 | G7: -9.1450531 | H7: {=getdistance($C$2,$D$2,F7,G7)} -> #NAME? | I7: {=getdistance($C$3,$D$3,F7,G7)} -> #NAME?
A8: 7 | B8: R. Luz Soriano 67 3º Andar - Sala 42A | C8: 38.71239 | D8: -9.1457974 | E8: PSP - 14ª Esquadra (Chelas) | F8: 38.753238 | G8: -9.1142988 | H8: {=getdistance($C$2,$D$2,F8,G8)} -> #NAME? | I8: {=getdistance($C$3,$D$3,F8,G8)} -> #NAME?
A9: 8 | B9: R. Áurea 223 | C9: 38.711761 | D9: -9.139086 | E9: PSP - 22ª Esquadra (Rato) | F9: 38.720502 | G9: -9.1558037 | H9: {=getdistance($C$2,$D$2,F9,G9)} -> #NAME? | I9: {=getdistance($C$3,$D$3,F9,G9)} -> #NAME?
A10: 9 | B10: R. Cozinha Económica 101 | C10: 38.703367 | D10: -9.1788123 | E10: PSP - Police 2nd Division - Olivais Sul | F10: 38.764061 | G10: -9.120155 | H10: {=getdistance($C$2,$D$2,F10,G10)} -> #NAME? | I10: {=getdistance($C$3,$D$3,F10,G10)} -> #NAME?
A11: 10 | B11: Escolas Gerais 42 | C11: 38.713737 | D11: -9.1285373 | E11: National Directorate of Police | F11: 38.729915 | G11: -9.1312807 | H11: {=getdistance($C$2,$D$2,F11,G11)} -> #NAME? | I11: {=getdistance($C$3,$D$3,F11,G11)} -> #NAME?
A12: 11 | B12: Av. de Roma 15 | C12: 38.767326 | D12: -9.1029762 | E12: PSP - 5ª Divisão Policial de Lisboa (Penha de França) | F12: 38.727782 | G12: -9.1274262 | H12: {=getdistance($C$2,$D$2,F12,G12)} -> #NAME? | I12: {=getdistance($C$3,$D$3,F12,G12)} -> #NAME?
A13: 12 | B13: R. Tomás da Anunciação 48B | C13: 38.716748 | D13: -9.1655396 | E13: PSP - 4ª Divisão Policial / 28ª Esquadra (Calvário) / 4ª Esquadra de Investigação Criminal de Lisboa | F13: 38.704463 | G13: -9.177761 | H13: {=getdistance($C$2,$D$2,F13,G13)} -> #NAME? | I13: {=getdistance($C$3,$D$3,F13,G13)} -> #NAME?
... A51: 50 | B51: R. de Buenos Aires 12B | C51: 38.710815 | D51: -9.1616018 | E51: PSP - Esquadra de Turismo e Secção de Achados (Santa Apolónia) | F51: 38.712795 | G51: -9.1250167 | H51: {=getdistance($C$2,$D$2,F51,G51)} -> #NAME? | I51: {=getdistance($C$3,$D$3,F51,G51)} -> #NAME?
A52: 51 | B52: Av. Visc. de Valmor 68 | C52: 38.73771 | D52: -9.1503769
A53: 52 | B53: Av. João XXI 70C | C53: 38.742301 | D53: -9.1417575
A54: 53 | B54: CC de Sant'Ana 180 | C54: 38.717649 | D54: -9.1389609
A55: 54 | B55: Estacionamento do Mercado do Chão do Loureiro, Largo Chão do Loureiro | C55: 38.712591 | D55: -9.1356808
A56: 55 | B56: Av. Fontes Pereira de Melo 42E | C56: 38.730768 | D56: -9.1470187
A57: 56 | B57: R. da Atalaia 204 | C57: 38.71444 | D57: -9.1453123
A58: 57 | B58: R. Barata Salgueiro 6A | C58: 38.722526 | D58: -9.146481
A59: 58 | B59: Praça Duque da Terceira CP | C59: 38.705883 | D59: -9.1443425
A60: 59 | B60: R. António Pereira Carrilho | C60: 38.73379 | D60: -9.1354628
A61: 60 | B61: R. do Poço dos Negros 94 | C61: 38.7101 | D61: -9.1512153
A62: 61 | B62: Av. Brasília 7 | C62: 38.699191 | D62: -9.1742789
A63: 62 | B63: R. Áurea 75 | C63: 38.709618 | D63: -9.1382223
... A124: 123 | B124: Cais do Sodré 22 | C124: 38.706694 | D124: -9.1472599

Sheet Sheet6
A1: Reference data from Data Set | D1: Calculated mway_dist of new co-ordinate collected through lookup on basis of coord_x(ref.)
